2020-05-19 15:48:15,381	INFO	django.server	"GET / HTTP/1.1" 302 0
2020-05-19 15:48:15,407	INFO	django.server	"GET /katana/login?next=/ HTTP/1.1" 301 0
2020-05-19 15:48:15,451	DEBUG	django.template	Exception while resolving variable 'userData' in template 'core/login.html'.
Traceback (most recent call last):
  File "/home/tony/Desktop/test/lib/python3.8/site-packages/django/template/base.py", line 829, in _resolve_lookup
    current = current[bit]
  File "/home/tony/Desktop/test/lib/python3.8/site-packages/django/template/context.py", line 83, in __getitem__
    raise KeyError(key)
KeyError: 'userData'

During handling of the above exception, another exception occurred:

Traceback (most recent call last):
  File "/home/tony/Desktop/test/lib/python3.8/site-packages/django/template/base.py", line 835, in _resolve_lookup
    if isinstance(current, BaseContext) and getattr(type(current), bit):
AttributeError: type object 'RequestContext' has no attribute 'userData'

During handling of the above exception, another exception occurred:

Traceback (most recent call last):
  File "/home/tony/Desktop/test/lib/python3.8/site-packages/django/template/base.py", line 843, in _resolve_lookup
    current = current[int(bit)]
ValueError: invalid literal for int() with base 10: 'userData'

During handling of the above exception, another exception occurred:

Traceback (most recent call last):
  File "/home/tony/Desktop/test/lib/python3.8/site-packages/django/template/base.py", line 848, in _resolve_lookup
    raise VariableDoesNotExist("Failed lookup for key "
django.template.base.VariableDoesNotExist: Failed lookup for key [userData] in [{'True': True, 'False': False, 'None': None}, {'csrf_token': <SimpleLazyObject: <function csrf.<locals>._get_val at 0x7fe61e397dc0>>, 'request': <WSGIRequest: GET '/katana/login/?next=/'>, 'user': <SimpleLazyObject: <django.contrib.auth.models.AnonymousUser object at 0x7fe61e38c2e0>>, 'perms': <django.contrib.auth.context_processors.PermWrapper object at 0x7fe61e3a2460>, 'messages': <django.contrib.messages.storage.fallback.FallbackStorage object at 0x7fe61e38c310>, 'DEFAULT_MESSAGE_LEVELS': {'DEBUG': 10, 'INFO': 20, 'SUCCESS': 25, 'WARNING': 30, 'ERROR': 40}}, {}, {'form': <AuthenticationForm bound=False, valid=Unknown, fields=(username;password)>, 'view': <katana.wui.core.views.LoginView object at 0x7fe61e38c340>, 'next': '/', 'site': <django.contrib.sites.requests.RequestSite object at 0x7fe61e38c670>, 'site_name': '127.0.0.1:7675'}, {}]
2020-05-19 15:48:15,453	DEBUG	django.template	Exception while resolving variable 'userData' in template 'core/login.html'.
Traceback (most recent call last):
  File "/home/tony/Desktop/test/lib/python3.8/site-packages/django/template/base.py", line 829, in _resolve_lookup
    current = current[bit]
  File "/home/tony/Desktop/test/lib/python3.8/site-packages/django/template/context.py", line 83, in __getitem__
    raise KeyError(key)
KeyError: 'userData'

During handling of the above exception, another exception occurred:

Traceback (most recent call last):
  File "/home/tony/Desktop/test/lib/python3.8/site-packages/django/template/base.py", line 835, in _resolve_lookup
    if isinstance(current, BaseContext) and getattr(type(current), bit):
AttributeError: type object 'RequestContext' has no attribute 'userData'

During handling of the above exception, another exception occurred:

Traceback (most recent call last):
  File "/home/tony/Desktop/test/lib/python3.8/site-packages/django/template/base.py", line 843, in _resolve_lookup
    current = current[int(bit)]
ValueError: invalid literal for int() with base 10: 'userData'

During handling of the above exception, another exception occurred:

Traceback (most recent call last):
  File "/home/tony/Desktop/test/lib/python3.8/site-packages/django/template/base.py", line 848, in _resolve_lookup
    raise VariableDoesNotExist("Failed lookup for key "
django.template.base.VariableDoesNotExist: Failed lookup for key [userData] in [{'True': True, 'False': False, 'None': None}, {'csrf_token': <SimpleLazyObject: <function csrf.<locals>._get_val at 0x7fe61e397dc0>>, 'request': <WSGIRequest: GET '/katana/login/?next=/'>, 'user': <SimpleLazyObject: <django.contrib.auth.models.AnonymousUser object at 0x7fe61e38c2e0>>, 'perms': <django.contrib.auth.context_processors.PermWrapper object at 0x7fe61e3a2460>, 'messages': <django.contrib.messages.storage.fallback.FallbackStorage object at 0x7fe61e38c310>, 'DEFAULT_MESSAGE_LEVELS': {'DEBUG': 10, 'INFO': 20, 'SUCCESS': 25, 'WARNING': 30, 'ERROR': 40}}, {}, {'form': <AuthenticationForm bound=False, valid=Unknown, fields=(username;password)>, 'view': <katana.wui.core.views.LoginView object at 0x7fe61e38c340>, 'next': '/', 'site': <django.contrib.sites.requests.RequestSite object at 0x7fe61e38c670>, 'site_name': '127.0.0.1:7675'}, {}]
2020-05-19 15:48:15,457	DEBUG	django.template	Exception while resolving variable 'frame_name' in template 'core/login.html'.
Traceback (most recent call last):
  File "/home/tony/Desktop/test/lib/python3.8/site-packages/django/template/base.py", line 829, in _resolve_lookup
    current = current[bit]
  File "/home/tony/Desktop/test/lib/python3.8/site-packages/django/template/context.py", line 83, in __getitem__
    raise KeyError(key)
KeyError: 'frame_name'

During handling of the above exception, another exception occurred:

Traceback (most recent call last):
  File "/home/tony/Desktop/test/lib/python3.8/site-packages/django/template/base.py", line 835, in _resolve_lookup
    if isinstance(current, BaseContext) and getattr(type(current), bit):
AttributeError: type object 'RequestContext' has no attribute 'frame_name'

During handling of the above exception, another exception occurred:

Traceback (most recent call last):
  File "/home/tony/Desktop/test/lib/python3.8/site-packages/django/template/base.py", line 843, in _resolve_lookup
    current = current[int(bit)]
ValueError: invalid literal for int() with base 10: 'frame_name'

During handling of the above exception, another exception occurred:

Traceback (most recent call last):
  File "/home/tony/Desktop/test/lib/python3.8/site-packages/django/template/base.py", line 848, in _resolve_lookup
    raise VariableDoesNotExist("Failed lookup for key "
django.template.base.VariableDoesNotExist: Failed lookup for key [frame_name] in [{'True': True, 'False': False, 'None': None}, {'csrf_token': <SimpleLazyObject: <function csrf.<locals>._get_val at 0x7fe61e397dc0>>, 'request': <WSGIRequest: GET '/katana/login/?next=/'>, 'user': <SimpleLazyObject: <django.contrib.auth.models.AnonymousUser object at 0x7fe61e38c2e0>>, 'perms': <django.contrib.auth.context_processors.PermWrapper object at 0x7fe61e3a2460>, 'messages': <django.contrib.messages.storage.fallback.FallbackStorage object at 0x7fe61e38c310>, 'DEFAULT_MESSAGE_LEVELS': {'DEBUG': 10, 'INFO': 20, 'SUCCESS': 25, 'WARNING': 30, 'ERROR': 40}}, {}, {'form': <AuthenticationForm bound=False, valid=Unknown, fields=(username;password)>, 'view': <katana.wui.core.views.LoginView object at 0x7fe61e38c340>, 'next': '/', 'site': <django.contrib.sites.requests.RequestSite object at 0x7fe61e38c670>, 'site_name': '127.0.0.1:7675'}, {'show_quick_user': 1}]
2020-05-19 15:48:15,464	INFO	django.server	"GET /katana/login/?next=/ HTTP/1.1" 200 6089
2020-05-19 15:48:15,826	INFO	django.server	"GET /static/oss/js/jquery.min.js HTTP/1.1" 200 86659
2020-05-19 15:48:15,843	INFO	django.server	"GET /static/oss/js/jquery-resizable.js HTTP/1.1" 200 6591
2020-05-19 15:48:15,857	INFO	django.server	"GET /static/oss/js/jquery-ui.min.js HTTP/1.1" 200 253668
2020-05-19 15:48:15,885	INFO	django.server	"GET /static/core/js/main.js HTTP/1.1" 200 50790
2020-05-19 15:48:15,888	INFO	django.server	"GET /static/oss/js/jstree.min.js HTTP/1.1" 200 135948
2020-05-19 15:48:15,891	INFO	django.server	"GET /static/oss/fonts/font-awesome-4.7.0/css/font-awesome.css HTTP/1.1" 200 37414
2020-05-19 15:48:15,907	INFO	django.server	"GET /static/oss/js/d3v4/d3.min.js HTTP/1.1" 200 220104
2020-05-19 15:48:15,909	INFO	django.server	"GET /static/oss/css/bootstrap.min.css HTTP/1.1" 200 124962
2020-05-19 15:48:15,933	INFO	django.server	"GET /static/oss/bootstrap-4.1.3/js/bootstrap.min.js HTTP/1.1" 200 51039
2020-05-19 15:48:15,937	INFO	django.server	"GET /static/core/css/panel_color.css HTTP/1.1" 200 28
2020-05-19 15:48:15,951	INFO	django.server	"GET /static/core/css/main.css HTTP/1.1" 200 55263
2020-05-19 15:48:15,981	INFO	django.server	"GET /static/oss/css/jstree/jstree.min.css HTTP/1.1" 200 27081
2020-05-19 15:48:16,002	INFO	django.server	"GET /static/core/images/logo.png HTTP/1.1" 200 29775
2020-05-19 15:48:16,347	INFO	django.server	"GET /static/oss/fonts/font-awesome-4.7.0/fonts/fontawesome-webfont.woff2?v=4.7.0 HTTP/1.1" 200 77160
2020-05-19 15:48:45,880	INFO	django.server	"POST /katana/login/ HTTP/1.1" 302 0
2020-05-19 15:48:45,916	INFO	django.server	"GET / HTTP/1.1" 302 0
2020-05-19 15:48:45,966	DEBUG	django.template	Exception while resolving variable 'pure_django' in template 'core/unified_index.html'.
Traceback (most recent call last):
  File "/home/tony/Desktop/test/lib/python3.8/site-packages/django/template/base.py", line 829, in _resolve_lookup
    current = current[bit]
KeyError: 'pure_django'

During handling of the above exception, another exception occurred:

Traceback (most recent call last):
  File "/home/tony/Desktop/test/lib/python3.8/site-packages/django/template/base.py", line 837, in _resolve_lookup
    current = getattr(current, bit)
AttributeError: 'dict' object has no attribute 'pure_django'

During handling of the above exception, another exception occurred:

Traceback (most recent call last):
  File "/home/tony/Desktop/test/lib/python3.8/site-packages/django/template/base.py", line 843, in _resolve_lookup
    current = current[int(bit)]
ValueError: invalid literal for int() with base 10: 'pure_django'

During handling of the above exception, another exception occurred:

Traceback (most recent call last):
  File "/home/tony/Desktop/test/lib/python3.8/site-packages/django/template/base.py", line 848, in _resolve_lookup
    raise VariableDoesNotExist("Failed lookup for key "
django.template.base.VariableDoesNotExist: Failed lookup for key [pure_django] in {'icon': 'cube', 'color': 'green', 'developer': 'Warrior Framework', 'description': 'MicroService Store', 'app': {'name': 'MicroService', 'url': '/katana/microservice_store/', 'include': 'wapps.microservice_store.urls'}, 'warrior-compatibility': ':warrior-4.0.0-beta', 'warrior-incompatibility': '', 'version': '1.0.0', 'permissions': '', 'availability': '', 'js_urls': ['/static/microservice_store/js/microservice_store.js']}
2020-05-19 15:48:45,967	DEBUG	django.template	Exception while resolving variable 'pure_django' in template 'core/unified_index.html'.
Traceback (most recent call last):
  File "/home/tony/Desktop/test/lib/python3.8/site-packages/django/template/base.py", line 829, in _resolve_lookup
    current = current[bit]
KeyError: 'pure_django'

During handling of the above exception, another exception occurred:

Traceback (most recent call last):
  File "/home/tony/Desktop/test/lib/python3.8/site-packages/django/template/base.py", line 837, in _resolve_lookup
    current = getattr(current, bit)
AttributeError: 'dict' object has no attribute 'pure_django'

During handling of the above exception, another exception occurred:

Traceback (most recent call last):
  File "/home/tony/Desktop/test/lib/python3.8/site-packages/django/template/base.py", line 843, in _resolve_lookup
    current = current[int(bit)]
ValueError: invalid literal for int() with base 10: 'pure_django'

During handling of the above exception, another exception occurred:

Traceback (most recent call last):
  File "/home/tony/Desktop/test/lib/python3.8/site-packages/django/template/base.py", line 848, in _resolve_lookup
    raise VariableDoesNotExist("Failed lookup for key "
django.template.base.VariableDoesNotExist: Failed lookup for key [pure_django] in {'icon': 'wrench', 'color': 'red', 'developer': 'Warrior Framework', 'description': 'Manage your wapps with this wapp manager.', 'app': {'name': 'Wapp Management', 'url': '/katana/wapp_management/', 'include': 'native.wapp_management.urls'}, 'warrior-compatibility': ':warrior-3.7.0', 'warrior-incompatibility': '', 'version': '1.0.0', 'permissions': '', 'availability': '', 'js_urls': ['/static/wapp_management/js/wapp_management.js']}
2020-05-19 15:48:45,967	DEBUG	django.template	Exception while resolving variable 'pure_django' in template 'core/unified_index.html'.
Traceback (most recent call last):
  File "/home/tony/Desktop/test/lib/python3.8/site-packages/django/template/base.py", line 829, in _resolve_lookup
    current = current[bit]
KeyError: 'pure_django'

During handling of the above exception, another exception occurred:

Traceback (most recent call last):
  File "/home/tony/Desktop/test/lib/python3.8/site-packages/django/template/base.py", line 837, in _resolve_lookup
    current = getattr(current, bit)
AttributeError: 'dict' object has no attribute 'pure_django'

During handling of the above exception, another exception occurred:

Traceback (most recent call last):
  File "/home/tony/Desktop/test/lib/python3.8/site-packages/django/template/base.py", line 843, in _resolve_lookup
    current = current[int(bit)]
ValueError: invalid literal for int() with base 10: 'pure_django'

During handling of the above exception, another exception occurred:

Traceback (most recent call last):
  File "/home/tony/Desktop/test/lib/python3.8/site-packages/django/template/base.py", line 848, in _resolve_lookup
    raise VariableDoesNotExist("Failed lookup for key "
django.template.base.VariableDoesNotExist: Failed lookup for key [pure_django] in {'icon': 'gamepad', 'color': 'green', 'developer': 'Warrior Framework', 'description': 'This is the Official Warrior App Store', 'app': {'name': 'Wapp Store', 'url': '/katana/wappstore/', 'include': 'native.wappstore.urls'}, 'warrior-compatibility': ':warrior-3.7.0', 'warrior-incompatibility': '', 'version': '1.0.0', 'permissions': '', 'availability': '', 'js_urls': ['/static/wappstore/js/wappstore.js']}
2020-05-19 15:48:45,968	DEBUG	django.template	Exception while resolving variable 'pure_django' in template 'core/unified_index.html'.
Traceback (most recent call last):
  File "/home/tony/Desktop/test/lib/python3.8/site-packages/django/template/base.py", line 829, in _resolve_lookup
    current = current[bit]
KeyError: 'pure_django'

During handling of the above exception, another exception occurred:

Traceback (most recent call last):
  File "/home/tony/Desktop/test/lib/python3.8/site-packages/django/template/base.py", line 837, in _resolve_lookup
    current = getattr(current, bit)
AttributeError: 'dict' object has no attribute 'pure_django'

During handling of the above exception, another exception occurred:

Traceback (most recent call last):
  File "/home/tony/Desktop/test/lib/python3.8/site-packages/django/template/base.py", line 843, in _resolve_lookup
    current = current[int(bit)]
ValueError: invalid literal for int() with base 10: 'pure_django'

During handling of the above exception, another exception occurred:

Traceback (most recent call last):
  File "/home/tony/Desktop/test/lib/python3.8/site-packages/django/template/base.py", line 848, in _resolve_lookup
    raise VariableDoesNotExist("Failed lookup for key "
django.template.base.VariableDoesNotExist: Failed lookup for key [pure_django] in {'icon': 'play-circle', 'color': 'blue', 'developer': 'Warrior Framework', 'description': 'Execute Warrior CLI  using the App', 'app': {'name': 'Execution', 'url': '/katana/execution/', 'include': 'wapps.execution.urls'}, 'warrior-compatibility': ':warrior-4.0.0-beta', 'warrior-incompatibility': '', 'version': '1.0.0', 'permissions': '', 'availability': '', 'js_urls': ['/static/execution/js/execution.js', '/static/execution/js/sortable.js', '/static/execution/js/cmdBuilder.js', '/static/execution/js/questionaire.js']}
2020-05-19 15:48:45,969	DEBUG	django.template	Exception while resolving variable 'pure_django' in template 'core/unified_index.html'.
Traceback (most recent call last):
  File "/home/tony/Desktop/test/lib/python3.8/site-packages/django/template/base.py", line 829, in _resolve_lookup
    current = current[bit]
KeyError: 'pure_django'

During handling of the above exception, another exception occurred:

Traceback (most recent call last):
  File "/home/tony/Desktop/test/lib/python3.8/site-packages/django/template/base.py", line 837, in _resolve_lookup
    current = getattr(current, bit)
AttributeError: 'dict' object has no attribute 'pure_django'

During handling of the above exception, another exception occurred:

Traceback (most recent call last):
  File "/home/tony/Desktop/test/lib/python3.8/site-packages/django/template/base.py", line 843, in _resolve_lookup
    current = current[int(bit)]
ValueError: invalid literal for int() with base 10: 'pure_django'

During handling of the above exception, another exception occurred:

Traceback (most recent call last):
  File "/home/tony/Desktop/test/lib/python3.8/site-packages/django/template/base.py", line 848, in _resolve_lookup
    raise VariableDoesNotExist("Failed lookup for key "
django.template.base.VariableDoesNotExist: Failed lookup for key [pure_django] in {'icon': 'map-signs', 'color': 'yellow', 'developer': 'Warrior Framework', 'description': 'Edit your CLI Data Files here', 'app': {'name': 'CLI Data', 'url': '/katana/cli_data/', 'include': 'wapps.cli_data.urls'}, 'warrior-compatibility': ':warrior-4.0.0-beta', 'warrior-incompatibility': '', 'version': '1.0.0', 'permissions': '', 'availability': '', 'js_urls': ['/static/cli_data/js/cli_data.js', '/static/cli_data/js/classes.js']}
2020-05-19 15:48:45,970	DEBUG	django.template	Exception while resolving variable 'pure_django' in template 'core/unified_index.html'.
Traceback (most recent call last):
  File "/home/tony/Desktop/test/lib/python3.8/site-packages/django/template/base.py", line 829, in _resolve_lookup
    current = current[bit]
KeyError: 'pure_django'

During handling of the above exception, another exception occurred:

Traceback (most recent call last):
  File "/home/tony/Desktop/test/lib/python3.8/site-packages/django/template/base.py", line 837, in _resolve_lookup
    current = getattr(current, bit)
AttributeError: 'dict' object has no attribute 'pure_django'

During handling of the above exception, another exception occurred:

Traceback (most recent call last):
  File "/home/tony/Desktop/test/lib/python3.8/site-packages/django/template/base.py", line 843, in _resolve_lookup
    current = current[int(bit)]
ValueError: invalid literal for int() with base 10: 'pure_django'

During handling of the above exception, another exception occurred:

Traceback (most recent call last):
  File "/home/tony/Desktop/test/lib/python3.8/site-packages/django/template/base.py", line 848, in _resolve_lookup
    raise VariableDoesNotExist("Failed lookup for key "
django.template.base.VariableDoesNotExist: Failed lookup for key [pure_django] in {'icon': 'th-large', 'color': 'lightblue', 'developer': 'Warrior Framework', 'description': 'Edit your Suites Files here.', 'app': {'name': 'Suites', 'url': '/katana/suites/', 'include': 'wapps.suites.urls'}, 'warrior-compatibility': ':warrior-4.0.0-beta', 'warrior-incompatibility': '', 'version': '1.0.0', 'permissions': '', 'availability': '', 'js_urls': ['/static/suites/js/suites.js']}
2020-05-19 15:48:45,971	DEBUG	django.template	Exception while resolving variable 'pure_django' in template 'core/unified_index.html'.
Traceback (most recent call last):
  File "/home/tony/Desktop/test/lib/python3.8/site-packages/django/template/base.py", line 829, in _resolve_lookup
    current = current[bit]
KeyError: 'pure_django'

During handling of the above exception, another exception occurred:

Traceback (most recent call last):
  File "/home/tony/Desktop/test/lib/python3.8/site-packages/django/template/base.py", line 837, in _resolve_lookup
    current = getattr(current, bit)
AttributeError: 'dict' object has no attribute 'pure_django'

During handling of the above exception, another exception occurred:

Traceback (most recent call last):
  File "/home/tony/Desktop/test/lib/python3.8/site-packages/django/template/base.py", line 843, in _resolve_lookup
    current = current[int(bit)]
ValueError: invalid literal for int() with base 10: 'pure_django'

During handling of the above exception, another exception occurred:

Traceback (most recent call last):
  File "/home/tony/Desktop/test/lib/python3.8/site-packages/django/template/base.py", line 848, in _resolve_lookup
    raise VariableDoesNotExist("Failed lookup for key "
django.template.base.VariableDoesNotExist: Failed lookup for key [pure_django] in {'icon': 'file-text', 'color': 'blue', 'developer': 'Warrior Framework', 'description': 'Edit your wrapper files with this App', 'app': {'name': 'TestWrapper', 'url': '/katana/testwrapper/', 'include': 'wapps.testwrapper.urls'}, 'warrior-compatibility': ':warrior-4.0.0-beta', 'warrior-incompatibility': '', 'version': '1.0.0', 'permissions': '', 'availability': '', 'js_urls': ['/static/testwrapper/js/generateJson.js', '/static/testwrapper/js/cases.js']}
2020-05-19 15:48:45,972	DEBUG	django.template	Exception while resolving variable 'pure_django' in template 'core/unified_index.html'.
Traceback (most recent call last):
  File "/home/tony/Desktop/test/lib/python3.8/site-packages/django/template/base.py", line 829, in _resolve_lookup
    current = current[bit]
KeyError: 'pure_django'

During handling of the above exception, another exception occurred:

Traceback (most recent call last):
  File "/home/tony/Desktop/test/lib/python3.8/site-packages/django/template/base.py", line 837, in _resolve_lookup
    current = getattr(current, bit)
AttributeError: 'dict' object has no attribute 'pure_django'

During handling of the above exception, another exception occurred:

Traceback (most recent call last):
  File "/home/tony/Desktop/test/lib/python3.8/site-packages/django/template/base.py", line 843, in _resolve_lookup
    current = current[int(bit)]
ValueError: invalid literal for int() with base 10: 'pure_django'

During handling of the above exception, another exception occurred:

Traceback (most recent call last):
  File "/home/tony/Desktop/test/lib/python3.8/site-packages/django/template/base.py", line 848, in _resolve_lookup
    raise VariableDoesNotExist("Failed lookup for key "
django.template.base.VariableDoesNotExist: Failed lookup for key [pure_django] in {'icon': 'briefcase', 'color': 'red', 'developer': 'Warrior Framework', 'description': 'Edit your Cases with this App', 'app': {'name': 'Cases', 'url': '/katana/cases/', 'include': 'wapps.cases.urls'}, 'warrior-compatibility': ':warrior-4.0.0-beta', 'warrior-incompatibility': '', 'version': '1.0.0', 'permissions': '', 'availability': '', 'js_urls': ['/static/cases/js/generateJson.js', '/static/cases/js/cases.js']}
2020-05-19 15:48:45,973	DEBUG	django.template	Exception while resolving variable 'pure_django' in template 'core/unified_index.html'.
Traceback (most recent call last):
  File "/home/tony/Desktop/test/lib/python3.8/site-packages/django/template/base.py", line 829, in _resolve_lookup
    current = current[bit]
KeyError: 'pure_django'

During handling of the above exception, another exception occurred:

Traceback (most recent call last):
  File "/home/tony/Desktop/test/lib/python3.8/site-packages/django/template/base.py", line 837, in _resolve_lookup
    current = getattr(current, bit)
AttributeError: 'dict' object has no attribute 'pure_django'

During handling of the above exception, another exception occurred:

Traceback (most recent call last):
  File "/home/tony/Desktop/test/lib/python3.8/site-packages/django/template/base.py", line 843, in _resolve_lookup
    current = current[int(bit)]
ValueError: invalid literal for int() with base 10: 'pure_django'

During handling of the above exception, another exception occurred:

Traceback (most recent call last):
  File "/home/tony/Desktop/test/lib/python3.8/site-packages/django/template/base.py", line 848, in _resolve_lookup
    raise VariableDoesNotExist("Failed lookup for key "
django.template.base.VariableDoesNotExist: Failed lookup for key [pure_django] in {'icon': 'cubes', 'color': 'lightred', 'developer': 'Warrior Framework', 'description': 'Edit your Projects Files here.', 'app': {'name': 'Projects', 'url': '/katana/projects/', 'include': 'wapps.projects.urls'}, 'warrior-compatibility': ':warrior-4.0.0-beta', 'warrior-incompatibility': '', 'version': '1.0.0', 'permissions': '', 'availability': '', 'js_urls': ['/static/projects/js/projects.js']}
2020-05-19 15:48:45,974	DEBUG	django.template	Exception while resolving variable 'pure_django' in template 'core/unified_index.html'.
Traceback (most recent call last):
  File "/home/tony/Desktop/test/lib/python3.8/site-packages/django/template/base.py", line 829, in _resolve_lookup
    current = current[bit]
KeyError: 'pure_django'

During handling of the above exception, another exception occurred:

Traceback (most recent call last):
  File "/home/tony/Desktop/test/lib/python3.8/site-packages/django/template/base.py", line 837, in _resolve_lookup
    current = getattr(current, bit)
AttributeError: 'dict' object has no attribute 'pure_django'

During handling of the above exception, another exception occurred:

Traceback (most recent call last):
  File "/home/tony/Desktop/test/lib/python3.8/site-packages/django/template/base.py", line 843, in _resolve_lookup
    current = current[int(bit)]
ValueError: invalid literal for int() with base 10: 'pure_django'

During handling of the above exception, another exception occurred:

Traceback (most recent call last):
  File "/home/tony/Desktop/test/lib/python3.8/site-packages/django/template/base.py", line 848, in _resolve_lookup
    raise VariableDoesNotExist("Failed lookup for key "
django.template.base.VariableDoesNotExist: Failed lookup for key [pure_django] in {'icon': 'cog', 'color': 'blue', 'developer': 'Warrior Framework', 'description': 'Lets you manage your Warrior settings', 'app': {'name': ' Warrior Settings', 'url': '/katana/settings/', 'include': 'native.settings.urls'}, 'warrior-compatibility': ':warrior-3.7.0', 'warrior-incompatibility': '', 'version': '1.0.0', 'permissions': '', 'availability': '', 'js_urls': ['/static/settings/js/settings.js']}
2020-05-19 15:48:45,975	DEBUG	django.template	Exception while resolving variable 'pure_django' in template 'core/unified_index.html'.
Traceback (most recent call last):
  File "/home/tony/Desktop/test/lib/python3.8/site-packages/django/template/base.py", line 829, in _resolve_lookup
    current = current[bit]
KeyError: 'pure_django'

During handling of the above exception, another exception occurred:

Traceback (most recent call last):
  File "/home/tony/Desktop/test/lib/python3.8/site-packages/django/template/base.py", line 837, in _resolve_lookup
    current = getattr(current, bit)
AttributeError: 'dict' object has no attribute 'pure_django'

During handling of the above exception, another exception occurred:

Traceback (most recent call last):
  File "/home/tony/Desktop/test/lib/python3.8/site-packages/django/template/base.py", line 843, in _resolve_lookup
    current = current[int(bit)]
ValueError: invalid literal for int() with base 10: 'pure_django'

During handling of the above exception, another exception occurred:

Traceback (most recent call last):
  File "/home/tony/Desktop/test/lib/python3.8/site-packages/django/template/base.py", line 848, in _resolve_lookup
    raise VariableDoesNotExist("Failed lookup for key "
django.template.base.VariableDoesNotExist: Failed lookup for key [pure_django] in {'icon': 'paper-plane', 'color': 'green', 'developer': 'Warrior Framework', 'description': 'Edit System Data here.', 'app': {'name': 'WDF Editor', 'url': '/katana/wdf/', 'include': 'wapps.wdf_edit.urls'}, 'warrior-compatibility': ':warrior-4.0.0-beta', 'warrior-incompatibility': '', 'version': '1.0.0', 'permissions': '', 'availability': '', 'js_urls': ['/static/wdf_edit/js/main.js']}
2020-05-19 15:48:45,976	DEBUG	django.template	Exception while resolving variable 'pure_django' in template 'core/unified_index.html'.
Traceback (most recent call last):
  File "/home/tony/Desktop/test/lib/python3.8/site-packages/django/template/base.py", line 829, in _resolve_lookup
    current = current[bit]
KeyError: 'pure_django'

During handling of the above exception, another exception occurred:

Traceback (most recent call last):
  File "/home/tony/Desktop/test/lib/python3.8/site-packages/django/template/base.py", line 837, in _resolve_lookup
    current = getattr(current, bit)
AttributeError: 'dict' object has no attribute 'pure_django'

During handling of the above exception, another exception occurred:

Traceback (most recent call last):
  File "/home/tony/Desktop/test/lib/python3.8/site-packages/django/template/base.py", line 843, in _resolve_lookup
    current = current[int(bit)]
ValueError: invalid literal for int() with base 10: 'pure_django'

During handling of the above exception, another exception occurred:

Traceback (most recent call last):
  File "/home/tony/Desktop/test/lib/python3.8/site-packages/django/template/base.py", line 848, in _resolve_lookup
    raise VariableDoesNotExist("Failed lookup for key "
django.template.base.VariableDoesNotExist: Failed lookup for key [pure_django] in {'icon': 'truck', 'color': 'tan', 'developer': 'Warrior Framework', 'description': 'Manage your Warrior Environment with this App', 'app': {'name': 'Assembler', 'url': '/katana/assembler/', 'include': 'wapps.assembler.urls'}, 'warrior-compatibility': ':warrior-4.0.0-beta', 'warrior-incompatibility': '', 'version': '1.0.0', 'permissions': '', 'availability': '', 'js_urls': ['/static/assembler/js/classUtils.js', '/static/assembler/js/assembler.js']}
2020-05-19 15:48:45,981	INFO	django.server	"GET /katana/ HTTP/1.1" 200 11063
2020-05-19 15:48:46,339	INFO	django.server	"GET /static/oss/js/jquery.min.js HTTP/1.1" 304 0
2020-05-19 15:48:46,345	INFO	django.server	"GET /static/oss/js/jquery-ui.min.js HTTP/1.1" 304 0
2020-05-19 15:48:46,348	INFO	django.server	"GET /static/core/js/main.js HTTP/1.1" 304 0
2020-05-19 15:48:46,361	INFO	django.server	"GET /static/oss/js/d3v4/d3.min.js HTTP/1.1" 304 0
2020-05-19 15:48:46,377	INFO	django.server	"GET /static/oss/js/jquery-resizable.js HTTP/1.1" 304 0
2020-05-19 15:48:46,377	INFO	django.server	"GET /static/oss/js/jstree.min.js HTTP/1.1" 304 0
2020-05-19 15:48:46,382	INFO	django.server	"GET /static/oss/fonts/font-awesome-4.7.0/css/font-awesome.css HTTP/1.1" 304 0
2020-05-19 15:48:46,401	INFO	django.server	"GET /static/oss/css/bootstrap.min.css HTTP/1.1" 304 0
2020-05-19 15:48:46,407	INFO	django.server	"GET /static/oss/css/jstree/jstree.min.css HTTP/1.1" 304 0
2020-05-19 15:48:46,408	INFO	django.server	"GET /static/core/css/panel_color.css HTTP/1.1" 304 0
2020-05-19 15:48:46,420	INFO	django.server	"GET /static/oss/bootstrap-4.1.3/js/bootstrap.min.js HTTP/1.1" 304 0
2020-05-19 15:48:46,422	INFO	django.server	"GET /static/core/css/main.css HTTP/1.1" 304 0
2020-05-19 15:48:46,662	INFO	django.server	"GET /static/core/images/logo.png HTTP/1.1" 304 0
2020-05-19 15:48:46,712	INFO	django.server	"GET /static/core/images/image.jpg HTTP/1.1" 200 13662
2020-05-19 15:49:26,010	INFO	django.server	"GET / HTTP/1.1" 302 0
2020-05-19 15:49:26,086	DEBUG	django.template	Exception while resolving variable 'pure_django' in template 'core/unified_index.html'.
Traceback (most recent call last):
  File "/home/tony/Desktop/test/lib/python3.8/site-packages/django/template/base.py", line 829, in _resolve_lookup
    current = current[bit]
KeyError: 'pure_django'

During handling of the above exception, another exception occurred:

Traceback (most recent call last):
  File "/home/tony/Desktop/test/lib/python3.8/site-packages/django/template/base.py", line 837, in _resolve_lookup
    current = getattr(current, bit)
AttributeError: 'dict' object has no attribute 'pure_django'

During handling of the above exception, another exception occurred:

Traceback (most recent call last):
  File "/home/tony/Desktop/test/lib/python3.8/site-packages/django/template/base.py", line 843, in _resolve_lookup
    current = current[int(bit)]
ValueError: invalid literal for int() with base 10: 'pure_django'

During handling of the above exception, another exception occurred:

Traceback (most recent call last):
  File "/home/tony/Desktop/test/lib/python3.8/site-packages/django/template/base.py", line 848, in _resolve_lookup
    raise VariableDoesNotExist("Failed lookup for key "
django.template.base.VariableDoesNotExist: Failed lookup for key [pure_django] in {'icon': 'cog', 'color': 'blue', 'developer': 'Warrior Framework', 'description': 'Lets you manage your Warrior settings', 'app': {'name': ' Warrior Settings', 'url': '/katana/settings/', 'include': 'native.settings.urls'}, 'warrior-compatibility': ':warrior-3.7.0', 'warrior-incompatibility': '', 'version': '1.0.0', 'permissions': '', 'availability': '', 'js_urls': ['/static/settings/js/settings.js']}
2020-05-19 15:49:26,088	DEBUG	django.template	Exception while resolving variable 'pure_django' in template 'core/unified_index.html'.
Traceback (most recent call last):
  File "/home/tony/Desktop/test/lib/python3.8/site-packages/django/template/base.py", line 829, in _resolve_lookup
    current = current[bit]
KeyError: 'pure_django'

During handling of the above exception, another exception occurred:

Traceback (most recent call last):
  File "/home/tony/Desktop/test/lib/python3.8/site-packages/django/template/base.py", line 837, in _resolve_lookup
    current = getattr(current, bit)
AttributeError: 'dict' object has no attribute 'pure_django'

During handling of the above exception, another exception occurred:

Traceback (most recent call last):
  File "/home/tony/Desktop/test/lib/python3.8/site-packages/django/template/base.py", line 843, in _resolve_lookup
    current = current[int(bit)]
ValueError: invalid literal for int() with base 10: 'pure_django'

During handling of the above exception, another exception occurred:

Traceback (most recent call last):
  File "/home/tony/Desktop/test/lib/python3.8/site-packages/django/template/base.py", line 848, in _resolve_lookup
    raise VariableDoesNotExist("Failed lookup for key "
django.template.base.VariableDoesNotExist: Failed lookup for key [pure_django] in {'icon': 'briefcase', 'color': 'red', 'developer': 'Warrior Framework', 'description': 'Edit your Cases with this App', 'app': {'name': 'Cases', 'url': '/katana/cases/', 'include': 'wapps.cases.urls'}, 'warrior-compatibility': ':warrior-4.0.0-beta', 'warrior-incompatibility': '', 'version': '1.0.0', 'permissions': '', 'availability': '', 'js_urls': ['/static/cases/js/generateJson.js', '/static/cases/js/cases.js']}
2020-05-19 15:49:26,089	DEBUG	django.template	Exception while resolving variable 'pure_django' in template 'core/unified_index.html'.
Traceback (most recent call last):
  File "/home/tony/Desktop/test/lib/python3.8/site-packages/django/template/base.py", line 829, in _resolve_lookup
    current = current[bit]
KeyError: 'pure_django'

During handling of the above exception, another exception occurred:

Traceback (most recent call last):
  File "/home/tony/Desktop/test/lib/python3.8/site-packages/django/template/base.py", line 837, in _resolve_lookup
    current = getattr(current, bit)
AttributeError: 'dict' object has no attribute 'pure_django'

During handling of the above exception, another exception occurred:

Traceback (most recent call last):
  File "/home/tony/Desktop/test/lib/python3.8/site-packages/django/template/base.py", line 843, in _resolve_lookup
    current = current[int(bit)]
ValueError: invalid literal for int() with base 10: 'pure_django'

During handling of the above exception, another exception occurred:

Traceback (most recent call last):
  File "/home/tony/Desktop/test/lib/python3.8/site-packages/django/template/base.py", line 848, in _resolve_lookup
    raise VariableDoesNotExist("Failed lookup for key "
django.template.base.VariableDoesNotExist: Failed lookup for key [pure_django] in {'icon': 'paper-plane', 'color': 'green', 'developer': 'Warrior Framework', 'description': 'Edit System Data here.', 'app': {'name': 'WDF Editor', 'url': '/katana/wdf/', 'include': 'wapps.wdf_edit.urls'}, 'warrior-compatibility': ':warrior-4.0.0-beta', 'warrior-incompatibility': '', 'version': '1.0.0', 'permissions': '', 'availability': '', 'js_urls': ['/static/wdf_edit/js/main.js']}
2020-05-19 15:49:26,090	DEBUG	django.template	Exception while resolving variable 'pure_django' in template 'core/unified_index.html'.
Traceback (most recent call last):
  File "/home/tony/Desktop/test/lib/python3.8/site-packages/django/template/base.py", line 829, in _resolve_lookup
    current = current[bit]
KeyError: 'pure_django'

During handling of the above exception, another exception occurred:

Traceback (most recent call last):
  File "/home/tony/Desktop/test/lib/python3.8/site-packages/django/template/base.py", line 837, in _resolve_lookup
    current = getattr(current, bit)
AttributeError: 'dict' object has no attribute 'pure_django'

During handling of the above exception, another exception occurred:

Traceback (most recent call last):
  File "/home/tony/Desktop/test/lib/python3.8/site-packages/django/template/base.py", line 843, in _resolve_lookup
    current = current[int(bit)]
ValueError: invalid literal for int() with base 10: 'pure_django'

During handling of the above exception, another exception occurred:

Traceback (most recent call last):
  File "/home/tony/Desktop/test/lib/python3.8/site-packages/django/template/base.py", line 848, in _resolve_lookup
    raise VariableDoesNotExist("Failed lookup for key "
django.template.base.VariableDoesNotExist: Failed lookup for key [pure_django] in {'icon': 'gamepad', 'color': 'green', 'developer': 'Warrior Framework', 'description': 'This is the Official Warrior App Store', 'app': {'name': 'Wapp Store', 'url': '/katana/wappstore/', 'include': 'native.wappstore.urls'}, 'warrior-compatibility': ':warrior-3.7.0', 'warrior-incompatibility': '', 'version': '1.0.0', 'permissions': '', 'availability': '', 'js_urls': ['/static/wappstore/js/wappstore.js']}
2020-05-19 15:49:26,090	DEBUG	django.template	Exception while resolving variable 'pure_django' in template 'core/unified_index.html'.
Traceback (most recent call last):
  File "/home/tony/Desktop/test/lib/python3.8/site-packages/django/template/base.py", line 829, in _resolve_lookup
    current = current[bit]
KeyError: 'pure_django'

During handling of the above exception, another exception occurred:

Traceback (most recent call last):
  File "/home/tony/Desktop/test/lib/python3.8/site-packages/django/template/base.py", line 837, in _resolve_lookup
    current = getattr(current, bit)
AttributeError: 'dict' object has no attribute 'pure_django'

During handling of the above exception, another exception occurred:

Traceback (most recent call last):
  File "/home/tony/Desktop/test/lib/python3.8/site-packages/django/template/base.py", line 843, in _resolve_lookup
    current = current[int(bit)]
ValueError: invalid literal for int() with base 10: 'pure_django'

During handling of the above exception, another exception occurred:

Traceback (most recent call last):
  File "/home/tony/Desktop/test/lib/python3.8/site-packages/django/template/base.py", line 848, in _resolve_lookup
    raise VariableDoesNotExist("Failed lookup for key "
django.template.base.VariableDoesNotExist: Failed lookup for key [pure_django] in {'icon': 'wrench', 'color': 'red', 'developer': 'Warrior Framework', 'description': 'Manage your wapps with this wapp manager.', 'app': {'name': 'Wapp Management', 'url': '/katana/wapp_management/', 'include': 'native.wapp_management.urls'}, 'warrior-compatibility': ':warrior-3.7.0', 'warrior-incompatibility': '', 'version': '1.0.0', 'permissions': '', 'availability': '', 'js_urls': ['/static/wapp_management/js/wapp_management.js']}
2020-05-19 15:49:26,091	DEBUG	django.template	Exception while resolving variable 'pure_django' in template 'core/unified_index.html'.
Traceback (most recent call last):
  File "/home/tony/Desktop/test/lib/python3.8/site-packages/django/template/base.py", line 829, in _resolve_lookup
    current = current[bit]
KeyError: 'pure_django'

During handling of the above exception, another exception occurred:

Traceback (most recent call last):
  File "/home/tony/Desktop/test/lib/python3.8/site-packages/django/template/base.py", line 837, in _resolve_lookup
    current = getattr(current, bit)
AttributeError: 'dict' object has no attribute 'pure_django'

During handling of the above exception, another exception occurred:

Traceback (most recent call last):
  File "/home/tony/Desktop/test/lib/python3.8/site-packages/django/template/base.py", line 843, in _resolve_lookup
    current = current[int(bit)]
ValueError: invalid literal for int() with base 10: 'pure_django'

During handling of the above exception, another exception occurred:

Traceback (most recent call last):
  File "/home/tony/Desktop/test/lib/python3.8/site-packages/django/template/base.py", line 848, in _resolve_lookup
    raise VariableDoesNotExist("Failed lookup for key "
django.template.base.VariableDoesNotExist: Failed lookup for key [pure_django] in {'icon': 'th-large', 'color': 'lightblue', 'developer': 'Warrior Framework', 'description': 'Edit your Suites Files here.', 'app': {'name': 'Suites', 'url': '/katana/suites/', 'include': 'wapps.suites.urls'}, 'warrior-compatibility': ':warrior-4.0.0-beta', 'warrior-incompatibility': '', 'version': '1.0.0', 'permissions': '', 'availability': '', 'js_urls': ['/static/suites/js/suites.js']}
2020-05-19 15:49:26,092	DEBUG	django.template	Exception while resolving variable 'pure_django' in template 'core/unified_index.html'.
Traceback (most recent call last):
  File "/home/tony/Desktop/test/lib/python3.8/site-packages/django/template/base.py", line 829, in _resolve_lookup
    current = current[bit]
KeyError: 'pure_django'

During handling of the above exception, another exception occurred:

Traceback (most recent call last):
  File "/home/tony/Desktop/test/lib/python3.8/site-packages/django/template/base.py", line 837, in _resolve_lookup
    current = getattr(current, bit)
AttributeError: 'dict' object has no attribute 'pure_django'

During handling of the above exception, another exception occurred:

Traceback (most recent call last):
  File "/home/tony/Desktop/test/lib/python3.8/site-packages/django/template/base.py", line 843, in _resolve_lookup
    current = current[int(bit)]
ValueError: invalid literal for int() with base 10: 'pure_django'

During handling of the above exception, another exception occurred:

Traceback (most recent call last):
  File "/home/tony/Desktop/test/lib/python3.8/site-packages/django/template/base.py", line 848, in _resolve_lookup
    raise VariableDoesNotExist("Failed lookup for key "
django.template.base.VariableDoesNotExist: Failed lookup for key [pure_django] in {'icon': 'file-text', 'color': 'blue', 'developer': 'Warrior Framework', 'description': 'Edit your wrapper files with this App', 'app': {'name': 'TestWrapper', 'url': '/katana/testwrapper/', 'include': 'wapps.testwrapper.urls'}, 'warrior-compatibility': ':warrior-4.0.0-beta', 'warrior-incompatibility': '', 'version': '1.0.0', 'permissions': '', 'availability': '', 'js_urls': ['/static/testwrapper/js/generateJson.js', '/static/testwrapper/js/cases.js']}
2020-05-19 15:49:26,094	DEBUG	django.template	Exception while resolving variable 'pure_django' in template 'core/unified_index.html'.
Traceback (most recent call last):
  File "/home/tony/Desktop/test/lib/python3.8/site-packages/django/template/base.py", line 829, in _resolve_lookup
    current = current[bit]
KeyError: 'pure_django'

During handling of the above exception, another exception occurred:

Traceback (most recent call last):
  File "/home/tony/Desktop/test/lib/python3.8/site-packages/django/template/base.py", line 837, in _resolve_lookup
    current = getattr(current, bit)
AttributeError: 'dict' object has no attribute 'pure_django'

During handling of the above exception, another exception occurred:

Traceback (most recent call last):
  File "/home/tony/Desktop/test/lib/python3.8/site-packages/django/template/base.py", line 843, in _resolve_lookup
    current = current[int(bit)]
ValueError: invalid literal for int() with base 10: 'pure_django'

During handling of the above exception, another exception occurred:

Traceback (most recent call last):
  File "/home/tony/Desktop/test/lib/python3.8/site-packages/django/template/base.py", line 848, in _resolve_lookup
    raise VariableDoesNotExist("Failed lookup for key "
django.template.base.VariableDoesNotExist: Failed lookup for key [pure_django] in {'icon': 'truck', 'color': 'tan', 'developer': 'Warrior Framework', 'description': 'Manage your Warrior Environment with this App', 'app': {'name': 'Assembler', 'url': '/katana/assembler/', 'include': 'wapps.assembler.urls'}, 'warrior-compatibility': ':warrior-4.0.0-beta', 'warrior-incompatibility': '', 'version': '1.0.0', 'permissions': '', 'availability': '', 'js_urls': ['/static/assembler/js/classUtils.js', '/static/assembler/js/assembler.js']}
2020-05-19 15:49:26,095	DEBUG	django.template	Exception while resolving variable 'pure_django' in template 'core/unified_index.html'.
Traceback (most recent call last):
  File "/home/tony/Desktop/test/lib/python3.8/site-packages/django/template/base.py", line 829, in _resolve_lookup
    current = current[bit]
KeyError: 'pure_django'

During handling of the above exception, another exception occurred:

Traceback (most recent call last):
  File "/home/tony/Desktop/test/lib/python3.8/site-packages/django/template/base.py", line 837, in _resolve_lookup
    current = getattr(current, bit)
AttributeError: 'dict' object has no attribute 'pure_django'

During handling of the above exception, another exception occurred:

Traceback (most recent call last):
  File "/home/tony/Desktop/test/lib/python3.8/site-packages/django/template/base.py", line 843, in _resolve_lookup
    current = current[int(bit)]
ValueError: invalid literal for int() with base 10: 'pure_django'

During handling of the above exception, another exception occurred:

Traceback (most recent call last):
  File "/home/tony/Desktop/test/lib/python3.8/site-packages/django/template/base.py", line 848, in _resolve_lookup
    raise VariableDoesNotExist("Failed lookup for key "
django.template.base.VariableDoesNotExist: Failed lookup for key [pure_django] in {'icon': 'play-circle', 'color': 'blue', 'developer': 'Warrior Framework', 'description': 'Execute Warrior CLI  using the App', 'app': {'name': 'Execution', 'url': '/katana/execution/', 'include': 'wapps.execution.urls'}, 'warrior-compatibility': ':warrior-4.0.0-beta', 'warrior-incompatibility': '', 'version': '1.0.0', 'permissions': '', 'availability': '', 'js_urls': ['/static/execution/js/execution.js', '/static/execution/js/sortable.js', '/static/execution/js/cmdBuilder.js', '/static/execution/js/questionaire.js']}
2020-05-19 15:49:26,096	DEBUG	django.template	Exception while resolving variable 'pure_django' in template 'core/unified_index.html'.
Traceback (most recent call last):
  File "/home/tony/Desktop/test/lib/python3.8/site-packages/django/template/base.py", line 829, in _resolve_lookup
    current = current[bit]
KeyError: 'pure_django'

During handling of the above exception, another exception occurred:

Traceback (most recent call last):
  File "/home/tony/Desktop/test/lib/python3.8/site-packages/django/template/base.py", line 837, in _resolve_lookup
    current = getattr(current, bit)
AttributeError: 'dict' object has no attribute 'pure_django'

During handling of the above exception, another exception occurred:

Traceback (most recent call last):
  File "/home/tony/Desktop/test/lib/python3.8/site-packages/django/template/base.py", line 843, in _resolve_lookup
    current = current[int(bit)]
ValueError: invalid literal for int() with base 10: 'pure_django'

During handling of the above exception, another exception occurred:

Traceback (most recent call last):
  File "/home/tony/Desktop/test/lib/python3.8/site-packages/django/template/base.py", line 848, in _resolve_lookup
    raise VariableDoesNotExist("Failed lookup for key "
django.template.base.VariableDoesNotExist: Failed lookup for key [pure_django] in {'icon': 'cubes', 'color': 'lightred', 'developer': 'Warrior Framework', 'description': 'Edit your Projects Files here.', 'app': {'name': 'Projects', 'url': '/katana/projects/', 'include': 'wapps.projects.urls'}, 'warrior-compatibility': ':warrior-4.0.0-beta', 'warrior-incompatibility': '', 'version': '1.0.0', 'permissions': '', 'availability': '', 'js_urls': ['/static/projects/js/projects.js']}
2020-05-19 15:49:26,097	DEBUG	django.template	Exception while resolving variable 'pure_django' in template 'core/unified_index.html'.
Traceback (most recent call last):
  File "/home/tony/Desktop/test/lib/python3.8/site-packages/django/template/base.py", line 829, in _resolve_lookup
    current = current[bit]
KeyError: 'pure_django'

During handling of the above exception, another exception occurred:

Traceback (most recent call last):
  File "/home/tony/Desktop/test/lib/python3.8/site-packages/django/template/base.py", line 837, in _resolve_lookup
    current = getattr(current, bit)
AttributeError: 'dict' object has no attribute 'pure_django'

During handling of the above exception, another exception occurred:

Traceback (most recent call last):
  File "/home/tony/Desktop/test/lib/python3.8/site-packages/django/template/base.py", line 843, in _resolve_lookup
    current = current[int(bit)]
ValueError: invalid literal for int() with base 10: 'pure_django'

During handling of the above exception, another exception occurred:

Traceback (most recent call last):
  File "/home/tony/Desktop/test/lib/python3.8/site-packages/django/template/base.py", line 848, in _resolve_lookup
    raise VariableDoesNotExist("Failed lookup for key "
django.template.base.VariableDoesNotExist: Failed lookup for key [pure_django] in {'icon': 'map-signs', 'color': 'yellow', 'developer': 'Warrior Framework', 'description': 'Edit your CLI Data Files here', 'app': {'name': 'CLI Data', 'url': '/katana/cli_data/', 'include': 'wapps.cli_data.urls'}, 'warrior-compatibility': ':warrior-4.0.0-beta', 'warrior-incompatibility': '', 'version': '1.0.0', 'permissions': '', 'availability': '', 'js_urls': ['/static/cli_data/js/cli_data.js', '/static/cli_data/js/classes.js']}
2020-05-19 15:49:26,098	DEBUG	django.template	Exception while resolving variable 'pure_django' in template 'core/unified_index.html'.
Traceback (most recent call last):
  File "/home/tony/Desktop/test/lib/python3.8/site-packages/django/template/base.py", line 829, in _resolve_lookup
    current = current[bit]
KeyError: 'pure_django'

During handling of the above exception, another exception occurred:

Traceback (most recent call last):
  File "/home/tony/Desktop/test/lib/python3.8/site-packages/django/template/base.py", line 837, in _resolve_lookup
    current = getattr(current, bit)
AttributeError: 'dict' object has no attribute 'pure_django'

During handling of the above exception, another exception occurred:

Traceback (most recent call last):
  File "/home/tony/Desktop/test/lib/python3.8/site-packages/django/template/base.py", line 843, in _resolve_lookup
    current = current[int(bit)]
ValueError: invalid literal for int() with base 10: 'pure_django'

During handling of the above exception, another exception occurred:

Traceback (most recent call last):
  File "/home/tony/Desktop/test/lib/python3.8/site-packages/django/template/base.py", line 848, in _resolve_lookup
    raise VariableDoesNotExist("Failed lookup for key "
django.template.base.VariableDoesNotExist: Failed lookup for key [pure_django] in {'icon': 'cube', 'color': 'green', 'developer': 'Warrior Framework', 'description': 'MicroService Store', 'app': {'name': 'MicroService', 'url': '/katana/microservice_store/', 'include': 'wapps.microservice_store.urls'}, 'warrior-compatibility': ':warrior-4.0.0-beta', 'warrior-incompatibility': '', 'version': '1.0.0', 'permissions': '', 'availability': '', 'js_urls': ['/static/microservice_store/js/microservice_store.js']}
2020-05-19 15:49:26,102	INFO	django.server	"GET /katana/ HTTP/1.1" 200 11063
2020-05-19 15:49:26,507	INFO	django.server	"GET /static/oss/js/jquery.min.js HTTP/1.1" 304 0
2020-05-19 15:49:26,512	INFO	django.server	"GET /static/oss/js/jquery-ui.min.js HTTP/1.1" 304 0
2020-05-19 15:49:26,529	INFO	django.server	"GET /static/oss/js/jquery-resizable.js HTTP/1.1" 304 0
2020-05-19 15:49:26,538	INFO	django.server	"GET /static/core/js/main.js HTTP/1.1" 304 0
2020-05-19 15:49:26,547	INFO	django.server	"GET /static/oss/js/jstree.min.js HTTP/1.1" 304 0
2020-05-19 15:49:26,557	INFO	django.server	"GET /static/oss/js/d3v4/d3.min.js HTTP/1.1" 304 0
2020-05-19 15:49:26,572	INFO	django.server	"GET /static/oss/fonts/font-awesome-4.7.0/css/font-awesome.css HTTP/1.1" 304 0
2020-05-19 15:49:26,573	INFO	django.server	"GET /static/oss/bootstrap-4.1.3/js/bootstrap.min.js HTTP/1.1" 304 0
2020-05-19 15:49:26,578	INFO	django.server	"GET /static/oss/css/bootstrap.min.css HTTP/1.1" 304 0
2020-05-19 15:49:26,590	INFO	django.server	"GET /static/core/css/main.css HTTP/1.1" 304 0
2020-05-19 15:49:26,596	INFO	django.server	"GET /static/oss/css/jstree/jstree.min.css HTTP/1.1" 304 0
2020-05-19 15:49:26,602	INFO	django.server	"GET /static/core/css/panel_color.css HTTP/1.1" 304 0
2020-05-19 15:49:26,608	INFO	django.server	"GET /static/core/images/logo.png HTTP/1.1" 304 0
2020-05-19 15:49:26,919	INFO	django.server	"GET /static/core/images/image.jpg HTTP/1.1" 200 13662
2020-05-19 15:49:27,036	INFO	django.server	"GET /static/oss/fonts/font-awesome-4.7.0/fonts/fontawesome-webfont.woff2?v=4.7.0 HTTP/1.1" 200 77160
2020-05-19 15:50:43,360	INFO	django.server	"GET /katana/ HTTP/1.1" 200 7184
2020-05-19 15:50:43,612	INFO	django.server	"GET /static/oss/js/jquery.min.js HTTP/1.1" 304 0
2020-05-19 15:50:43,619	INFO	django.server	"GET /static/oss/js/jquery-ui.min.js HTTP/1.1" 304 0
2020-05-19 15:50:43,626	INFO	django.server	"GET /static/oss/js/jquery-resizable.js HTTP/1.1" 304 0
2020-05-19 15:50:43,658	INFO	django.server	"GET /static/core/js/main.js HTTP/1.1" 304 0
2020-05-19 15:50:43,664	INFO	django.server	"GET /static/oss/js/jstree.min.js HTTP/1.1" 304 0
2020-05-19 15:50:43,665	INFO	django.server	"GET /static/oss/js/d3v4/d3.min.js HTTP/1.1" 304 0
2020-05-19 15:50:43,673	INFO	django.server	"GET /static/oss/fonts/font-awesome-4.7.0/css/font-awesome.css HTTP/1.1" 304 0
2020-05-19 15:50:43,683	INFO	django.server	"GET /static/oss/css/bootstrap.min.css HTTP/1.1" 304 0
2020-05-19 15:50:43,694	INFO	django.server	"GET /static/core/css/panel_color.css HTTP/1.1" 200 28
2020-05-19 15:50:43,698	INFO	django.server	"GET /static/core/css/main.css HTTP/1.1" 304 0
2020-05-19 15:50:43,713	INFO	django.server	"GET /static/oss/bootstrap-4.1.3/js/bootstrap.min.js HTTP/1.1" 304 0
2020-05-19 15:50:43,718	INFO	django.server	"GET /static/oss/css/jstree/jstree.min.css HTTP/1.1" 304 0
2020-05-19 15:50:43,991	INFO	django.server	"GET /static/core/images/logo.png HTTP/1.1" 304 0
2020-05-19 15:50:44,018	INFO	django.server	"GET /static/core/images/image.jpg HTTP/1.1" 200 13662
2020-05-19 15:53:00,551	DEBUG	django.template	Exception while resolving variable 'pure_django' in template 'core/unified_index.html'.
Traceback (most recent call last):
  File "/home/tony/Desktop/test/lib/python3.8/site-packages/django/template/base.py", line 829, in _resolve_lookup
    current = current[bit]
KeyError: 'pure_django'

During handling of the above exception, another exception occurred:

Traceback (most recent call last):
  File "/home/tony/Desktop/test/lib/python3.8/site-packages/django/template/base.py", line 837, in _resolve_lookup
    current = getattr(current, bit)
AttributeError: 'dict' object has no attribute 'pure_django'

During handling of the above exception, another exception occurred:

Traceback (most recent call last):
  File "/home/tony/Desktop/test/lib/python3.8/site-packages/django/template/base.py", line 843, in _resolve_lookup
    current = current[int(bit)]
ValueError: invalid literal for int() with base 10: 'pure_django'

During handling of the above exception, another exception occurred:

Traceback (most recent call last):
  File "/home/tony/Desktop/test/lib/python3.8/site-packages/django/template/base.py", line 848, in _resolve_lookup
    raise VariableDoesNotExist("Failed lookup for key "
django.template.base.VariableDoesNotExist: Failed lookup for key [pure_django] in {'icon': 'paper-plane', 'color': 'green', 'developer': 'Warrior Framework', 'description': 'Edit System Data here.', 'app': {'name': 'WDF Editor', 'url': '/katana/wdf/', 'include': 'wapps.wdf_edit.urls'}, 'warrior-compatibility': ':warrior-4.0.0-beta', 'warrior-incompatibility': '', 'version': '1.0.0', 'permissions': '', 'availability': '', 'js_urls': ['/static/wdf_edit/js/main.js']}
2020-05-19 15:53:00,553	DEBUG	django.template	Exception while resolving variable 'pure_django' in template 'core/unified_index.html'.
Traceback (most recent call last):
  File "/home/tony/Desktop/test/lib/python3.8/site-packages/django/template/base.py", line 829, in _resolve_lookup
    current = current[bit]
KeyError: 'pure_django'

During handling of the above exception, another exception occurred:

Traceback (most recent call last):
  File "/home/tony/Desktop/test/lib/python3.8/site-packages/django/template/base.py", line 837, in _resolve_lookup
    current = getattr(current, bit)
AttributeError: 'dict' object has no attribute 'pure_django'

During handling of the above exception, another exception occurred:

Traceback (most recent call last):
  File "/home/tony/Desktop/test/lib/python3.8/site-packages/django/template/base.py", line 843, in _resolve_lookup
    current = current[int(bit)]
ValueError: invalid literal for int() with base 10: 'pure_django'

During handling of the above exception, another exception occurred:

Traceback (most recent call last):
  File "/home/tony/Desktop/test/lib/python3.8/site-packages/django/template/base.py", line 848, in _resolve_lookup
    raise VariableDoesNotExist("Failed lookup for key "
django.template.base.VariableDoesNotExist: Failed lookup for key [pure_django] in {'icon': 'wrench', 'color': 'red', 'developer': 'Warrior Framework', 'description': 'Manage your wapps with this wapp manager.', 'app': {'name': 'Wapp Management', 'url': '/katana/wapp_management/', 'include': 'native.wapp_management.urls'}, 'warrior-compatibility': ':warrior-3.7.0', 'warrior-incompatibility': '', 'version': '1.0.0', 'permissions': '', 'availability': '', 'js_urls': ['/static/wapp_management/js/wapp_management.js']}
2020-05-19 15:53:00,554	DEBUG	django.template	Exception while resolving variable 'pure_django' in template 'core/unified_index.html'.
Traceback (most recent call last):
  File "/home/tony/Desktop/test/lib/python3.8/site-packages/django/template/base.py", line 829, in _resolve_lookup
    current = current[bit]
KeyError: 'pure_django'

During handling of the above exception, another exception occurred:

Traceback (most recent call last):
  File "/home/tony/Desktop/test/lib/python3.8/site-packages/django/template/base.py", line 837, in _resolve_lookup
    current = getattr(current, bit)
AttributeError: 'dict' object has no attribute 'pure_django'

During handling of the above exception, another exception occurred:

Traceback (most recent call last):
  File "/home/tony/Desktop/test/lib/python3.8/site-packages/django/template/base.py", line 843, in _resolve_lookup
    current = current[int(bit)]
ValueError: invalid literal for int() with base 10: 'pure_django'

During handling of the above exception, another exception occurred:

Traceback (most recent call last):
  File "/home/tony/Desktop/test/lib/python3.8/site-packages/django/template/base.py", line 848, in _resolve_lookup
    raise VariableDoesNotExist("Failed lookup for key "
django.template.base.VariableDoesNotExist: Failed lookup for key [pure_django] in {'icon': 'file-text', 'color': 'blue', 'developer': 'Warrior Framework', 'description': 'Edit your wrapper files with this App', 'app': {'name': 'TestWrapper', 'url': '/katana/testwrapper/', 'include': 'wapps.testwrapper.urls'}, 'warrior-compatibility': ':warrior-4.0.0-beta', 'warrior-incompatibility': '', 'version': '1.0.0', 'permissions': '', 'availability': '', 'js_urls': ['/static/testwrapper/js/generateJson.js', '/static/testwrapper/js/cases.js']}
2020-05-19 15:53:00,555	DEBUG	django.template	Exception while resolving variable 'pure_django' in template 'core/unified_index.html'.
Traceback (most recent call last):
  File "/home/tony/Desktop/test/lib/python3.8/site-packages/django/template/base.py", line 829, in _resolve_lookup
    current = current[bit]
KeyError: 'pure_django'

During handling of the above exception, another exception occurred:

Traceback (most recent call last):
  File "/home/tony/Desktop/test/lib/python3.8/site-packages/django/template/base.py", line 837, in _resolve_lookup
    current = getattr(current, bit)
AttributeError: 'dict' object has no attribute 'pure_django'

During handling of the above exception, another exception occurred:

Traceback (most recent call last):
  File "/home/tony/Desktop/test/lib/python3.8/site-packages/django/template/base.py", line 843, in _resolve_lookup
    current = current[int(bit)]
ValueError: invalid literal for int() with base 10: 'pure_django'

During handling of the above exception, another exception occurred:

Traceback (most recent call last):
  File "/home/tony/Desktop/test/lib/python3.8/site-packages/django/template/base.py", line 848, in _resolve_lookup
    raise VariableDoesNotExist("Failed lookup for key "
django.template.base.VariableDoesNotExist: Failed lookup for key [pure_django] in {'icon': 'briefcase', 'color': 'red', 'developer': 'Warrior Framework', 'description': 'Edit your Cases with this App', 'app': {'name': 'Cases', 'url': '/katana/cases/', 'include': 'wapps.cases.urls'}, 'warrior-compatibility': ':warrior-4.0.0-beta', 'warrior-incompatibility': '', 'version': '1.0.0', 'permissions': '', 'availability': '', 'js_urls': ['/static/cases/js/generateJson.js', '/static/cases/js/cases.js']}
2020-05-19 15:53:00,556	DEBUG	django.template	Exception while resolving variable 'pure_django' in template 'core/unified_index.html'.
Traceback (most recent call last):
  File "/home/tony/Desktop/test/lib/python3.8/site-packages/django/template/base.py", line 829, in _resolve_lookup
    current = current[bit]
KeyError: 'pure_django'

During handling of the above exception, another exception occurred:

Traceback (most recent call last):
  File "/home/tony/Desktop/test/lib/python3.8/site-packages/django/template/base.py", line 837, in _resolve_lookup
    current = getattr(current, bit)
AttributeError: 'dict' object has no attribute 'pure_django'

During handling of the above exception, another exception occurred:

Traceback (most recent call last):
  File "/home/tony/Desktop/test/lib/python3.8/site-packages/django/template/base.py", line 843, in _resolve_lookup
    current = current[int(bit)]
ValueError: invalid literal for int() with base 10: 'pure_django'

During handling of the above exception, another exception occurred:

Traceback (most recent call last):
  File "/home/tony/Desktop/test/lib/python3.8/site-packages/django/template/base.py", line 848, in _resolve_lookup
    raise VariableDoesNotExist("Failed lookup for key "
django.template.base.VariableDoesNotExist: Failed lookup for key [pure_django] in {'icon': 'truck', 'color': 'tan', 'developer': 'Warrior Framework', 'description': 'Manage your Warrior Environment with this App', 'app': {'name': 'Assembler', 'url': '/katana/assembler/', 'include': 'wapps.assembler.urls'}, 'warrior-compatibility': ':warrior-4.0.0-beta', 'warrior-incompatibility': '', 'version': '1.0.0', 'permissions': '', 'availability': '', 'js_urls': ['/static/assembler/js/classUtils.js', '/static/assembler/js/assembler.js']}
2020-05-19 15:53:00,557	DEBUG	django.template	Exception while resolving variable 'pure_django' in template 'core/unified_index.html'.
Traceback (most recent call last):
  File "/home/tony/Desktop/test/lib/python3.8/site-packages/django/template/base.py", line 829, in _resolve_lookup
    current = current[bit]
KeyError: 'pure_django'

During handling of the above exception, another exception occurred:

Traceback (most recent call last):
  File "/home/tony/Desktop/test/lib/python3.8/site-packages/django/template/base.py", line 837, in _resolve_lookup
    current = getattr(current, bit)
AttributeError: 'dict' object has no attribute 'pure_django'

During handling of the above exception, another exception occurred:

Traceback (most recent call last):
  File "/home/tony/Desktop/test/lib/python3.8/site-packages/django/template/base.py", line 843, in _resolve_lookup
    current = current[int(bit)]
ValueError: invalid literal for int() with base 10: 'pure_django'

During handling of the above exception, another exception occurred:

Traceback (most recent call last):
  File "/home/tony/Desktop/test/lib/python3.8/site-packages/django/template/base.py", line 848, in _resolve_lookup
    raise VariableDoesNotExist("Failed lookup for key "
django.template.base.VariableDoesNotExist: Failed lookup for key [pure_django] in {'icon': 'cube', 'color': 'green', 'developer': 'Warrior Framework', 'description': 'MicroService Store', 'app': {'name': 'MicroService', 'url': '/katana/microservice_store/', 'include': 'wapps.microservice_store.urls'}, 'warrior-compatibility': ':warrior-4.0.0-beta', 'warrior-incompatibility': '', 'version': '1.0.0', 'permissions': '', 'availability': '', 'js_urls': ['/static/microservice_store/js/microservice_store.js']}
2020-05-19 15:53:00,558	DEBUG	django.template	Exception while resolving variable 'pure_django' in template 'core/unified_index.html'.
Traceback (most recent call last):
  File "/home/tony/Desktop/test/lib/python3.8/site-packages/django/template/base.py", line 829, in _resolve_lookup
    current = current[bit]
KeyError: 'pure_django'

During handling of the above exception, another exception occurred:

Traceback (most recent call last):
  File "/home/tony/Desktop/test/lib/python3.8/site-packages/django/template/base.py", line 837, in _resolve_lookup
    current = getattr(current, bit)
AttributeError: 'dict' object has no attribute 'pure_django'

During handling of the above exception, another exception occurred:

Traceback (most recent call last):
  File "/home/tony/Desktop/test/lib/python3.8/site-packages/django/template/base.py", line 843, in _resolve_lookup
    current = current[int(bit)]
ValueError: invalid literal for int() with base 10: 'pure_django'

During handling of the above exception, another exception occurred:

Traceback (most recent call last):
  File "/home/tony/Desktop/test/lib/python3.8/site-packages/django/template/base.py", line 848, in _resolve_lookup
    raise VariableDoesNotExist("Failed lookup for key "
django.template.base.VariableDoesNotExist: Failed lookup for key [pure_django] in {'icon': 'play-circle', 'color': 'blue', 'developer': 'Warrior Framework', 'description': 'Execute Warrior CLI  using the App', 'app': {'name': 'Execution', 'url': '/katana/execution/', 'include': 'wapps.execution.urls'}, 'warrior-compatibility': ':warrior-4.0.0-beta', 'warrior-incompatibility': '', 'version': '1.0.0', 'permissions': '', 'availability': '', 'js_urls': ['/static/execution/js/execution.js', '/static/execution/js/sortable.js', '/static/execution/js/cmdBuilder.js', '/static/execution/js/questionaire.js']}
2020-05-19 15:53:00,559	DEBUG	django.template	Exception while resolving variable 'pure_django' in template 'core/unified_index.html'.
Traceback (most recent call last):
  File "/home/tony/Desktop/test/lib/python3.8/site-packages/django/template/base.py", line 829, in _resolve_lookup
    current = current[bit]
KeyError: 'pure_django'

During handling of the above exception, another exception occurred:

Traceback (most recent call last):
  File "/home/tony/Desktop/test/lib/python3.8/site-packages/django/template/base.py", line 837, in _resolve_lookup
    current = getattr(current, bit)
AttributeError: 'dict' object has no attribute 'pure_django'

During handling of the above exception, another exception occurred:

Traceback (most recent call last):
  File "/home/tony/Desktop/test/lib/python3.8/site-packages/django/template/base.py", line 843, in _resolve_lookup
    current = current[int(bit)]
ValueError: invalid literal for int() with base 10: 'pure_django'

During handling of the above exception, another exception occurred:

Traceback (most recent call last):
  File "/home/tony/Desktop/test/lib/python3.8/site-packages/django/template/base.py", line 848, in _resolve_lookup
    raise VariableDoesNotExist("Failed lookup for key "
django.template.base.VariableDoesNotExist: Failed lookup for key [pure_django] in {'icon': 'map-signs', 'color': 'yellow', 'developer': 'Warrior Framework', 'description': 'Edit your CLI Data Files here', 'app': {'name': 'CLI Data', 'url': '/katana/cli_data/', 'include': 'wapps.cli_data.urls'}, 'warrior-compatibility': ':warrior-4.0.0-beta', 'warrior-incompatibility': '', 'version': '1.0.0', 'permissions': '', 'availability': '', 'js_urls': ['/static/cli_data/js/cli_data.js', '/static/cli_data/js/classes.js']}
2020-05-19 15:53:00,560	DEBUG	django.template	Exception while resolving variable 'pure_django' in template 'core/unified_index.html'.
Traceback (most recent call last):
  File "/home/tony/Desktop/test/lib/python3.8/site-packages/django/template/base.py", line 829, in _resolve_lookup
    current = current[bit]
KeyError: 'pure_django'

During handling of the above exception, another exception occurred:

Traceback (most recent call last):
  File "/home/tony/Desktop/test/lib/python3.8/site-packages/django/template/base.py", line 837, in _resolve_lookup
    current = getattr(current, bit)
AttributeError: 'dict' object has no attribute 'pure_django'

During handling of the above exception, another exception occurred:

Traceback (most recent call last):
  File "/home/tony/Desktop/test/lib/python3.8/site-packages/django/template/base.py", line 843, in _resolve_lookup
    current = current[int(bit)]
ValueError: invalid literal for int() with base 10: 'pure_django'

During handling of the above exception, another exception occurred:

Traceback (most recent call last):
  File "/home/tony/Desktop/test/lib/python3.8/site-packages/django/template/base.py", line 848, in _resolve_lookup
    raise VariableDoesNotExist("Failed lookup for key "
django.template.base.VariableDoesNotExist: Failed lookup for key [pure_django] in {'icon': 'cubes', 'color': 'lightred', 'developer': 'Warrior Framework', 'description': 'Edit your Projects Files here.', 'app': {'name': 'Projects', 'url': '/katana/projects/', 'include': 'wapps.projects.urls'}, 'warrior-compatibility': ':warrior-4.0.0-beta', 'warrior-incompatibility': '', 'version': '1.0.0', 'permissions': '', 'availability': '', 'js_urls': ['/static/projects/js/projects.js']}
2020-05-19 15:53:00,560	DEBUG	django.template	Exception while resolving variable 'pure_django' in template 'core/unified_index.html'.
Traceback (most recent call last):
  File "/home/tony/Desktop/test/lib/python3.8/site-packages/django/template/base.py", line 829, in _resolve_lookup
    current = current[bit]
KeyError: 'pure_django'

During handling of the above exception, another exception occurred:

Traceback (most recent call last):
  File "/home/tony/Desktop/test/lib/python3.8/site-packages/django/template/base.py", line 837, in _resolve_lookup
    current = getattr(current, bit)
AttributeError: 'dict' object has no attribute 'pure_django'

During handling of the above exception, another exception occurred:

Traceback (most recent call last):
  File "/home/tony/Desktop/test/lib/python3.8/site-packages/django/template/base.py", line 843, in _resolve_lookup
    current = current[int(bit)]
ValueError: invalid literal for int() with base 10: 'pure_django'

During handling of the above exception, another exception occurred:

Traceback (most recent call last):
  File "/home/tony/Desktop/test/lib/python3.8/site-packages/django/template/base.py", line 848, in _resolve_lookup
    raise VariableDoesNotExist("Failed lookup for key "
django.template.base.VariableDoesNotExist: Failed lookup for key [pure_django] in {'icon': 'cog', 'color': 'blue', 'developer': 'Warrior Framework', 'description': 'Lets you manage your Warrior settings', 'app': {'name': ' Warrior Settings', 'url': '/katana/settings/', 'include': 'native.settings.urls'}, 'warrior-compatibility': ':warrior-3.7.0', 'warrior-incompatibility': '', 'version': '1.0.0', 'permissions': '', 'availability': '', 'js_urls': ['/static/settings/js/settings.js']}
2020-05-19 15:53:00,561	DEBUG	django.template	Exception while resolving variable 'pure_django' in template 'core/unified_index.html'.
Traceback (most recent call last):
  File "/home/tony/Desktop/test/lib/python3.8/site-packages/django/template/base.py", line 829, in _resolve_lookup
    current = current[bit]
KeyError: 'pure_django'

During handling of the above exception, another exception occurred:

Traceback (most recent call last):
  File "/home/tony/Desktop/test/lib/python3.8/site-packages/django/template/base.py", line 837, in _resolve_lookup
    current = getattr(current, bit)
AttributeError: 'dict' object has no attribute 'pure_django'

During handling of the above exception, another exception occurred:

Traceback (most recent call last):
  File "/home/tony/Desktop/test/lib/python3.8/site-packages/django/template/base.py", line 843, in _resolve_lookup
    current = current[int(bit)]
ValueError: invalid literal for int() with base 10: 'pure_django'

During handling of the above exception, another exception occurred:

Traceback (most recent call last):
  File "/home/tony/Desktop/test/lib/python3.8/site-packages/django/template/base.py", line 848, in _resolve_lookup
    raise VariableDoesNotExist("Failed lookup for key "
django.template.base.VariableDoesNotExist: Failed lookup for key [pure_django] in {'icon': 'th-large', 'color': 'lightblue', 'developer': 'Warrior Framework', 'description': 'Edit your Suites Files here.', 'app': {'name': 'Suites', 'url': '/katana/suites/', 'include': 'wapps.suites.urls'}, 'warrior-compatibility': ':warrior-4.0.0-beta', 'warrior-incompatibility': '', 'version': '1.0.0', 'permissions': '', 'availability': '', 'js_urls': ['/static/suites/js/suites.js']}
2020-05-19 15:53:00,562	DEBUG	django.template	Exception while resolving variable 'pure_django' in template 'core/unified_index.html'.
Traceback (most recent call last):
  File "/home/tony/Desktop/test/lib/python3.8/site-packages/django/template/base.py", line 829, in _resolve_lookup
    current = current[bit]
KeyError: 'pure_django'

During handling of the above exception, another exception occurred:

Traceback (most recent call last):
  File "/home/tony/Desktop/test/lib/python3.8/site-packages/django/template/base.py", line 837, in _resolve_lookup
    current = getattr(current, bit)
AttributeError: 'dict' object has no attribute 'pure_django'

During handling of the above exception, another exception occurred:

Traceback (most recent call last):
  File "/home/tony/Desktop/test/lib/python3.8/site-packages/django/template/base.py", line 843, in _resolve_lookup
    current = current[int(bit)]
ValueError: invalid literal for int() with base 10: 'pure_django'

During handling of the above exception, another exception occurred:

Traceback (most recent call last):
  File "/home/tony/Desktop/test/lib/python3.8/site-packages/django/template/base.py", line 848, in _resolve_lookup
    raise VariableDoesNotExist("Failed lookup for key "
django.template.base.VariableDoesNotExist: Failed lookup for key [pure_django] in {'icon': 'gamepad', 'color': 'green', 'developer': 'Warrior Framework', 'description': 'This is the Official Warrior App Store', 'app': {'name': 'Wapp Store', 'url': '/katana/wappstore/', 'include': 'native.wappstore.urls'}, 'warrior-compatibility': ':warrior-3.7.0', 'warrior-incompatibility': '', 'version': '1.0.0', 'permissions': '', 'availability': '', 'js_urls': ['/static/wappstore/js/wappstore.js']}
2020-05-19 15:53:00,567	INFO	django.server	"GET /katana/ HTTP/1.1" 200 11063
2020-05-19 15:53:00,806	INFO	django.server	"GET /static/oss/js/d3v4/d3.min.js HTTP/1.1" 304 0
2020-05-19 15:53:00,815	INFO	django.server	"GET /static/oss/js/jstree.min.js HTTP/1.1" 304 0
2020-05-19 15:53:00,830	INFO	django.server	"GET /static/core/js/main.js HTTP/1.1" 304 0
2020-05-19 15:53:00,839	INFO	django.server	"GET /static/oss/js/jquery-resizable.js HTTP/1.1" 304 0
2020-05-19 15:53:00,853	INFO	django.server	"GET /static/oss/js/jquery.min.js HTTP/1.1" 304 0
2020-05-19 15:53:00,858	INFO	django.server	"GET /static/oss/js/jquery-ui.min.js HTTP/1.1" 304 0
2020-05-19 15:53:00,861	INFO	django.server	"GET /static/oss/css/jstree/jstree.min.css HTTP/1.1" 304 0
2020-05-19 15:53:00,864	INFO	django.server	"GET /static/oss/bootstrap-4.1.3/js/bootstrap.min.js HTTP/1.1" 304 0
2020-05-19 15:53:00,874	INFO	django.server	"GET /static/core/css/main.css HTTP/1.1" 304 0
2020-05-19 15:53:00,876	INFO	django.server	"GET /static/oss/fonts/font-awesome-4.7.0/css/font-awesome.css HTTP/1.1" 304 0
2020-05-19 15:53:00,884	INFO	django.server	"GET /static/oss/css/bootstrap.min.css HTTP/1.1" 304 0
2020-05-19 15:53:00,895	INFO	django.server	"GET /static/core/css/panel_color.css HTTP/1.1" 200 28
2020-05-19 15:53:01,038	INFO	django.server	"GET /static/core/images/logo.png HTTP/1.1" 304 0
2020-05-19 15:53:01,079	INFO	django.server	"GET /static/core/images/image.jpg HTTP/1.1" 200 13662
2020-05-19 15:56:21,710	INFO	django.server	"GET / HTTP/1.1" 302 0
2020-05-19 15:56:21,786	DEBUG	django.template	Exception while resolving variable 'pure_django' in template 'core/unified_index.html'.
Traceback (most recent call last):
  File "/home/tony/Desktop/test/lib/python3.8/site-packages/django/template/base.py", line 829, in _resolve_lookup
    current = current[bit]
KeyError: 'pure_django'

During handling of the above exception, another exception occurred:

Traceback (most recent call last):
  File "/home/tony/Desktop/test/lib/python3.8/site-packages/django/template/base.py", line 837, in _resolve_lookup
    current = getattr(current, bit)
AttributeError: 'dict' object has no attribute 'pure_django'

During handling of the above exception, another exception occurred:

Traceback (most recent call last):
  File "/home/tony/Desktop/test/lib/python3.8/site-packages/django/template/base.py", line 843, in _resolve_lookup
    current = current[int(bit)]
ValueError: invalid literal for int() with base 10: 'pure_django'

During handling of the above exception, another exception occurred:

Traceback (most recent call last):
  File "/home/tony/Desktop/test/lib/python3.8/site-packages/django/template/base.py", line 848, in _resolve_lookup
    raise VariableDoesNotExist("Failed lookup for key "
django.template.base.VariableDoesNotExist: Failed lookup for key [pure_django] in {'icon': 'briefcase', 'color': 'red', 'developer': 'Warrior Framework', 'description': 'Edit your Cases with this App', 'app': {'name': 'Cases', 'url': '/katana/cases/', 'include': 'wapps.cases.urls'}, 'warrior-compatibility': ':warrior-4.0.0-beta', 'warrior-incompatibility': '', 'version': '1.0.0', 'permissions': '', 'availability': '', 'js_urls': ['/static/cases/js/generateJson.js', '/static/cases/js/cases.js']}
2020-05-19 15:56:21,788	DEBUG	django.template	Exception while resolving variable 'pure_django' in template 'core/unified_index.html'.
Traceback (most recent call last):
  File "/home/tony/Desktop/test/lib/python3.8/site-packages/django/template/base.py", line 829, in _resolve_lookup
    current = current[bit]
KeyError: 'pure_django'

During handling of the above exception, another exception occurred:

Traceback (most recent call last):
  File "/home/tony/Desktop/test/lib/python3.8/site-packages/django/template/base.py", line 837, in _resolve_lookup
    current = getattr(current, bit)
AttributeError: 'dict' object has no attribute 'pure_django'

During handling of the above exception, another exception occurred:

Traceback (most recent call last):
  File "/home/tony/Desktop/test/lib/python3.8/site-packages/django/template/base.py", line 843, in _resolve_lookup
    current = current[int(bit)]
ValueError: invalid literal for int() with base 10: 'pure_django'

During handling of the above exception, another exception occurred:

Traceback (most recent call last):
  File "/home/tony/Desktop/test/lib/python3.8/site-packages/django/template/base.py", line 848, in _resolve_lookup
    raise VariableDoesNotExist("Failed lookup for key "
django.template.base.VariableDoesNotExist: Failed lookup for key [pure_django] in {'icon': 'cubes', 'color': 'lightred', 'developer': 'Warrior Framework', 'description': 'Edit your Projects Files here.', 'app': {'name': 'Projects', 'url': '/katana/projects/', 'include': 'wapps.projects.urls'}, 'warrior-compatibility': ':warrior-4.0.0-beta', 'warrior-incompatibility': '', 'version': '1.0.0', 'permissions': '', 'availability': '', 'js_urls': ['/static/projects/js/projects.js']}
2020-05-19 15:56:21,789	DEBUG	django.template	Exception while resolving variable 'pure_django' in template 'core/unified_index.html'.
Traceback (most recent call last):
  File "/home/tony/Desktop/test/lib/python3.8/site-packages/django/template/base.py", line 829, in _resolve_lookup
    current = current[bit]
KeyError: 'pure_django'

During handling of the above exception, another exception occurred:

Traceback (most recent call last):
  File "/home/tony/Desktop/test/lib/python3.8/site-packages/django/template/base.py", line 837, in _resolve_lookup
    current = getattr(current, bit)
AttributeError: 'dict' object has no attribute 'pure_django'

During handling of the above exception, another exception occurred:

Traceback (most recent call last):
  File "/home/tony/Desktop/test/lib/python3.8/site-packages/django/template/base.py", line 843, in _resolve_lookup
    current = current[int(bit)]
ValueError: invalid literal for int() with base 10: 'pure_django'

During handling of the above exception, another exception occurred:

Traceback (most recent call last):
  File "/home/tony/Desktop/test/lib/python3.8/site-packages/django/template/base.py", line 848, in _resolve_lookup
    raise VariableDoesNotExist("Failed lookup for key "
django.template.base.VariableDoesNotExist: Failed lookup for key [pure_django] in {'icon': 'play-circle', 'color': 'blue', 'developer': 'Warrior Framework', 'description': 'Execute Warrior CLI  using the App', 'app': {'name': 'Execution', 'url': '/katana/execution/', 'include': 'wapps.execution.urls'}, 'warrior-compatibility': ':warrior-4.0.0-beta', 'warrior-incompatibility': '', 'version': '1.0.0', 'permissions': '', 'availability': '', 'js_urls': ['/static/execution/js/execution.js', '/static/execution/js/sortable.js', '/static/execution/js/cmdBuilder.js', '/static/execution/js/questionaire.js']}
2020-05-19 15:56:21,790	DEBUG	django.template	Exception while resolving variable 'pure_django' in template 'core/unified_index.html'.
Traceback (most recent call last):
  File "/home/tony/Desktop/test/lib/python3.8/site-packages/django/template/base.py", line 829, in _resolve_lookup
    current = current[bit]
KeyError: 'pure_django'

During handling of the above exception, another exception occurred:

Traceback (most recent call last):
  File "/home/tony/Desktop/test/lib/python3.8/site-packages/django/template/base.py", line 837, in _resolve_lookup
    current = getattr(current, bit)
AttributeError: 'dict' object has no attribute 'pure_django'

During handling of the above exception, another exception occurred:

Traceback (most recent call last):
  File "/home/tony/Desktop/test/lib/python3.8/site-packages/django/template/base.py", line 843, in _resolve_lookup
    current = current[int(bit)]
ValueError: invalid literal for int() with base 10: 'pure_django'

During handling of the above exception, another exception occurred:

Traceback (most recent call last):
  File "/home/tony/Desktop/test/lib/python3.8/site-packages/django/template/base.py", line 848, in _resolve_lookup
    raise VariableDoesNotExist("Failed lookup for key "
django.template.base.VariableDoesNotExist: Failed lookup for key [pure_django] in {'icon': 'truck', 'color': 'tan', 'developer': 'Warrior Framework', 'description': 'Manage your Warrior Environment with this App', 'app': {'name': 'Assembler', 'url': '/katana/assembler/', 'include': 'wapps.assembler.urls'}, 'warrior-compatibility': ':warrior-4.0.0-beta', 'warrior-incompatibility': '', 'version': '1.0.0', 'permissions': '', 'availability': '', 'js_urls': ['/static/assembler/js/classUtils.js', '/static/assembler/js/assembler.js']}
2020-05-19 15:56:21,791	DEBUG	django.template	Exception while resolving variable 'pure_django' in template 'core/unified_index.html'.
Traceback (most recent call last):
  File "/home/tony/Desktop/test/lib/python3.8/site-packages/django/template/base.py", line 829, in _resolve_lookup
    current = current[bit]
KeyError: 'pure_django'

During handling of the above exception, another exception occurred:

Traceback (most recent call last):
  File "/home/tony/Desktop/test/lib/python3.8/site-packages/django/template/base.py", line 837, in _resolve_lookup
    current = getattr(current, bit)
AttributeError: 'dict' object has no attribute 'pure_django'

During handling of the above exception, another exception occurred:

Traceback (most recent call last):
  File "/home/tony/Desktop/test/lib/python3.8/site-packages/django/template/base.py", line 843, in _resolve_lookup
    current = current[int(bit)]
ValueError: invalid literal for int() with base 10: 'pure_django'

During handling of the above exception, another exception occurred:

Traceback (most recent call last):
  File "/home/tony/Desktop/test/lib/python3.8/site-packages/django/template/base.py", line 848, in _resolve_lookup
    raise VariableDoesNotExist("Failed lookup for key "
django.template.base.VariableDoesNotExist: Failed lookup for key [pure_django] in {'icon': 'cog', 'color': 'blue', 'developer': 'Warrior Framework', 'description': 'Lets you manage your Warrior settings', 'app': {'name': ' Warrior Settings', 'url': '/katana/settings/', 'include': 'native.settings.urls'}, 'warrior-compatibility': ':warrior-3.7.0', 'warrior-incompatibility': '', 'version': '1.0.0', 'permissions': '', 'availability': '', 'js_urls': ['/static/settings/js/settings.js']}
2020-05-19 15:56:21,792	DEBUG	django.template	Exception while resolving variable 'pure_django' in template 'core/unified_index.html'.
Traceback (most recent call last):
  File "/home/tony/Desktop/test/lib/python3.8/site-packages/django/template/base.py", line 829, in _resolve_lookup
    current = current[bit]
KeyError: 'pure_django'

During handling of the above exception, another exception occurred:

Traceback (most recent call last):
  File "/home/tony/Desktop/test/lib/python3.8/site-packages/django/template/base.py", line 837, in _resolve_lookup
    current = getattr(current, bit)
AttributeError: 'dict' object has no attribute 'pure_django'

During handling of the above exception, another exception occurred:

Traceback (most recent call last):
  File "/home/tony/Desktop/test/lib/python3.8/site-packages/django/template/base.py", line 843, in _resolve_lookup
    current = current[int(bit)]
ValueError: invalid literal for int() with base 10: 'pure_django'

During handling of the above exception, another exception occurred:

Traceback (most recent call last):
  File "/home/tony/Desktop/test/lib/python3.8/site-packages/django/template/base.py", line 848, in _resolve_lookup
    raise VariableDoesNotExist("Failed lookup for key "
django.template.base.VariableDoesNotExist: Failed lookup for key [pure_django] in {'icon': 'file-text', 'color': 'blue', 'developer': 'Warrior Framework', 'description': 'Edit your wrapper files with this App', 'app': {'name': 'TestWrapper', 'url': '/katana/testwrapper/', 'include': 'wapps.testwrapper.urls'}, 'warrior-compatibility': ':warrior-4.0.0-beta', 'warrior-incompatibility': '', 'version': '1.0.0', 'permissions': '', 'availability': '', 'js_urls': ['/static/testwrapper/js/generateJson.js', '/static/testwrapper/js/cases.js']}
2020-05-19 15:56:21,793	DEBUG	django.template	Exception while resolving variable 'pure_django' in template 'core/unified_index.html'.
Traceback (most recent call last):
  File "/home/tony/Desktop/test/lib/python3.8/site-packages/django/template/base.py", line 829, in _resolve_lookup
    current = current[bit]
KeyError: 'pure_django'

During handling of the above exception, another exception occurred:

Traceback (most recent call last):
  File "/home/tony/Desktop/test/lib/python3.8/site-packages/django/template/base.py", line 837, in _resolve_lookup
    current = getattr(current, bit)
AttributeError: 'dict' object has no attribute 'pure_django'

During handling of the above exception, another exception occurred:

Traceback (most recent call last):
  File "/home/tony/Desktop/test/lib/python3.8/site-packages/django/template/base.py", line 843, in _resolve_lookup
    current = current[int(bit)]
ValueError: invalid literal for int() with base 10: 'pure_django'

During handling of the above exception, another exception occurred:

Traceback (most recent call last):
  File "/home/tony/Desktop/test/lib/python3.8/site-packages/django/template/base.py", line 848, in _resolve_lookup
    raise VariableDoesNotExist("Failed lookup for key "
django.template.base.VariableDoesNotExist: Failed lookup for key [pure_django] in {'icon': 'wrench', 'color': 'red', 'developer': 'Warrior Framework', 'description': 'Manage your wapps with this wapp manager.', 'app': {'name': 'Wapp Management', 'url': '/katana/wapp_management/', 'include': 'native.wapp_management.urls'}, 'warrior-compatibility': ':warrior-3.7.0', 'warrior-incompatibility': '', 'version': '1.0.0', 'permissions': '', 'availability': '', 'js_urls': ['/static/wapp_management/js/wapp_management.js']}
2020-05-19 15:56:21,794	DEBUG	django.template	Exception while resolving variable 'pure_django' in template 'core/unified_index.html'.
Traceback (most recent call last):
  File "/home/tony/Desktop/test/lib/python3.8/site-packages/django/template/base.py", line 829, in _resolve_lookup
    current = current[bit]
KeyError: 'pure_django'

During handling of the above exception, another exception occurred:

Traceback (most recent call last):
  File "/home/tony/Desktop/test/lib/python3.8/site-packages/django/template/base.py", line 837, in _resolve_lookup
    current = getattr(current, bit)
AttributeError: 'dict' object has no attribute 'pure_django'

During handling of the above exception, another exception occurred:

Traceback (most recent call last):
  File "/home/tony/Desktop/test/lib/python3.8/site-packages/django/template/base.py", line 843, in _resolve_lookup
    current = current[int(bit)]
ValueError: invalid literal for int() with base 10: 'pure_django'

During handling of the above exception, another exception occurred:

Traceback (most recent call last):
  File "/home/tony/Desktop/test/lib/python3.8/site-packages/django/template/base.py", line 848, in _resolve_lookup
    raise VariableDoesNotExist("Failed lookup for key "
django.template.base.VariableDoesNotExist: Failed lookup for key [pure_django] in {'icon': 'cube', 'color': 'green', 'developer': 'Warrior Framework', 'description': 'MicroService Store', 'app': {'name': 'MicroService', 'url': '/katana/microservice_store/', 'include': 'wapps.microservice_store.urls'}, 'warrior-compatibility': ':warrior-4.0.0-beta', 'warrior-incompatibility': '', 'version': '1.0.0', 'permissions': '', 'availability': '', 'js_urls': ['/static/microservice_store/js/microservice_store.js']}
2020-05-19 15:56:21,795	DEBUG	django.template	Exception while resolving variable 'pure_django' in template 'core/unified_index.html'.
Traceback (most recent call last):
  File "/home/tony/Desktop/test/lib/python3.8/site-packages/django/template/base.py", line 829, in _resolve_lookup
    current = current[bit]
KeyError: 'pure_django'

During handling of the above exception, another exception occurred:

Traceback (most recent call last):
  File "/home/tony/Desktop/test/lib/python3.8/site-packages/django/template/base.py", line 837, in _resolve_lookup
    current = getattr(current, bit)
AttributeError: 'dict' object has no attribute 'pure_django'

During handling of the above exception, another exception occurred:

Traceback (most recent call last):
  File "/home/tony/Desktop/test/lib/python3.8/site-packages/django/template/base.py", line 843, in _resolve_lookup
    current = current[int(bit)]
ValueError: invalid literal for int() with base 10: 'pure_django'

During handling of the above exception, another exception occurred:

Traceback (most recent call last):
  File "/home/tony/Desktop/test/lib/python3.8/site-packages/django/template/base.py", line 848, in _resolve_lookup
    raise VariableDoesNotExist("Failed lookup for key "
django.template.base.VariableDoesNotExist: Failed lookup for key [pure_django] in {'icon': 'th-large', 'color': 'lightblue', 'developer': 'Warrior Framework', 'description': 'Edit your Suites Files here.', 'app': {'name': 'Suites', 'url': '/katana/suites/', 'include': 'wapps.suites.urls'}, 'warrior-compatibility': ':warrior-4.0.0-beta', 'warrior-incompatibility': '', 'version': '1.0.0', 'permissions': '', 'availability': '', 'js_urls': ['/static/suites/js/suites.js']}
2020-05-19 15:56:21,796	DEBUG	django.template	Exception while resolving variable 'pure_django' in template 'core/unified_index.html'.
Traceback (most recent call last):
  File "/home/tony/Desktop/test/lib/python3.8/site-packages/django/template/base.py", line 829, in _resolve_lookup
    current = current[bit]
KeyError: 'pure_django'

During handling of the above exception, another exception occurred:

Traceback (most recent call last):
  File "/home/tony/Desktop/test/lib/python3.8/site-packages/django/template/base.py", line 837, in _resolve_lookup
    current = getattr(current, bit)
AttributeError: 'dict' object has no attribute 'pure_django'

During handling of the above exception, another exception occurred:

Traceback (most recent call last):
  File "/home/tony/Desktop/test/lib/python3.8/site-packages/django/template/base.py", line 843, in _resolve_lookup
    current = current[int(bit)]
ValueError: invalid literal for int() with base 10: 'pure_django'

During handling of the above exception, another exception occurred:

Traceback (most recent call last):
  File "/home/tony/Desktop/test/lib/python3.8/site-packages/django/template/base.py", line 848, in _resolve_lookup
    raise VariableDoesNotExist("Failed lookup for key "
django.template.base.VariableDoesNotExist: Failed lookup for key [pure_django] in {'icon': 'paper-plane', 'color': 'green', 'developer': 'Warrior Framework', 'description': 'Edit System Data here.', 'app': {'name': 'WDF Editor', 'url': '/katana/wdf/', 'include': 'wapps.wdf_edit.urls'}, 'warrior-compatibility': ':warrior-4.0.0-beta', 'warrior-incompatibility': '', 'version': '1.0.0', 'permissions': '', 'availability': '', 'js_urls': ['/static/wdf_edit/js/main.js']}
2020-05-19 15:56:21,797	DEBUG	django.template	Exception while resolving variable 'pure_django' in template 'core/unified_index.html'.
Traceback (most recent call last):
  File "/home/tony/Desktop/test/lib/python3.8/site-packages/django/template/base.py", line 829, in _resolve_lookup
    current = current[bit]
KeyError: 'pure_django'

During handling of the above exception, another exception occurred:

Traceback (most recent call last):
  File "/home/tony/Desktop/test/lib/python3.8/site-packages/django/template/base.py", line 837, in _resolve_lookup
    current = getattr(current, bit)
AttributeError: 'dict' object has no attribute 'pure_django'

During handling of the above exception, another exception occurred:

Traceback (most recent call last):
  File "/home/tony/Desktop/test/lib/python3.8/site-packages/django/template/base.py", line 843, in _resolve_lookup
    current = current[int(bit)]
ValueError: invalid literal for int() with base 10: 'pure_django'

During handling of the above exception, another exception occurred:

Traceback (most recent call last):
  File "/home/tony/Desktop/test/lib/python3.8/site-packages/django/template/base.py", line 848, in _resolve_lookup
    raise VariableDoesNotExist("Failed lookup for key "
django.template.base.VariableDoesNotExist: Failed lookup for key [pure_django] in {'icon': 'map-signs', 'color': 'yellow', 'developer': 'Warrior Framework', 'description': 'Edit your CLI Data Files here', 'app': {'name': 'CLI Data', 'url': '/katana/cli_data/', 'include': 'wapps.cli_data.urls'}, 'warrior-compatibility': ':warrior-4.0.0-beta', 'warrior-incompatibility': '', 'version': '1.0.0', 'permissions': '', 'availability': '', 'js_urls': ['/static/cli_data/js/cli_data.js', '/static/cli_data/js/classes.js']}
2020-05-19 15:56:21,798	DEBUG	django.template	Exception while resolving variable 'pure_django' in template 'core/unified_index.html'.
Traceback (most recent call last):
  File "/home/tony/Desktop/test/lib/python3.8/site-packages/django/template/base.py", line 829, in _resolve_lookup
    current = current[bit]
KeyError: 'pure_django'

During handling of the above exception, another exception occurred:

Traceback (most recent call last):
  File "/home/tony/Desktop/test/lib/python3.8/site-packages/django/template/base.py", line 837, in _resolve_lookup
    current = getattr(current, bit)
AttributeError: 'dict' object has no attribute 'pure_django'

During handling of the above exception, another exception occurred:

Traceback (most recent call last):
  File "/home/tony/Desktop/test/lib/python3.8/site-packages/django/template/base.py", line 843, in _resolve_lookup
    current = current[int(bit)]
ValueError: invalid literal for int() with base 10: 'pure_django'

During handling of the above exception, another exception occurred:

Traceback (most recent call last):
  File "/home/tony/Desktop/test/lib/python3.8/site-packages/django/template/base.py", line 848, in _resolve_lookup
    raise VariableDoesNotExist("Failed lookup for key "
django.template.base.VariableDoesNotExist: Failed lookup for key [pure_django] in {'icon': 'gamepad', 'color': 'green', 'developer': 'Warrior Framework', 'description': 'This is the Official Warrior App Store', 'app': {'name': 'Wapp Store', 'url': '/katana/wappstore/', 'include': 'native.wappstore.urls'}, 'warrior-compatibility': ':warrior-3.7.0', 'warrior-incompatibility': '', 'version': '1.0.0', 'permissions': '', 'availability': '', 'js_urls': ['/static/wappstore/js/wappstore.js']}
2020-05-19 15:56:21,804	INFO	django.server	"GET /katana/ HTTP/1.1" 200 11063
2020-05-19 15:56:22,106	INFO	django.server	"GET /static/oss/js/jquery.min.js HTTP/1.1" 304 0
2020-05-19 15:56:22,115	INFO	django.server	"GET /static/oss/js/jquery-ui.min.js HTTP/1.1" 304 0
2020-05-19 15:56:22,122	INFO	django.server	"GET /static/oss/js/jquery-resizable.js HTTP/1.1" 304 0
2020-05-19 15:56:22,124	INFO	django.server	"GET /static/oss/js/d3v4/d3.min.js HTTP/1.1" 304 0
2020-05-19 15:56:22,124	INFO	django.server	"GET /static/oss/js/jstree.min.js HTTP/1.1" 304 0
2020-05-19 15:56:22,135	INFO	django.server	"GET /static/core/js/main.js HTTP/1.1" 304 0
2020-05-19 15:56:22,136	INFO	django.server	"GET /static/oss/bootstrap-4.1.3/js/bootstrap.min.js HTTP/1.1" 304 0
2020-05-19 15:56:22,159	INFO	django.server	"GET /static/core/images/logo.png HTTP/1.1" 304 0
2020-05-19 15:56:22,172	INFO	django.server	"GET /static/core/css/panel_color.css HTTP/1.1" 200 28
2020-05-19 15:56:22,176	INFO	django.server	"GET /static/core/css/main.css HTTP/1.1" 200 55263
2020-05-19 15:56:22,178	INFO	django.server	"GET /static/oss/css/jstree/jstree.min.css HTTP/1.1" 200 27081
2020-05-19 15:56:22,180	INFO	django.server	"GET /static/oss/fonts/font-awesome-4.7.0/css/font-awesome.css HTTP/1.1" 200 37414
2020-05-19 15:56:22,182	INFO	django.server	"GET /static/oss/css/bootstrap.min.css HTTP/1.1" 200 124962
2020-05-19 15:56:22,394	INFO	django.server	"GET /static/core/images/image.jpg HTTP/1.1" 200 13662
2020-05-19 15:56:22,479	INFO	django.server	"GET /static/oss/fonts/font-awesome-4.7.0/fonts/fontawesome-webfont.woff2?v=4.7.0 HTTP/1.1" 200 77160
